<sdf version='1.6'>
  <world name='default'>
    <light name='sun' type='directional'>
      <cast_shadows>1</cast_shadows>
      <pose frame=''>0 0 10 0 -0 0</pose>
      <diffuse>0.8 0.8 0.8 1</diffuse>
      <specular>0.2 0.2 0.2 1</specular>
      <attenuation>
        <range>1000</range>
        <constant>0.9</constant>
        <linear>0.01</linear>
        <quadratic>0.001</quadratic>
      </attenuation>
      <direction>-0.5 0.1 -0.9</direction>
    </light>
    <model name='ground_plane'>
      <static>1</static>
      <link name='link'>
        <collision name='collision'>
          <geometry>
            <plane>
              <normal>0 0 1</normal>
              <size>100 100</size>
            </plane>
          </geometry>
          <surface>
            <contact>
              <collide_bitmask>65535</collide_bitmask>
              <ode/>
            </contact>
            <friction>
              <ode>
                <mu>100</mu>
                <mu2>50</mu2>
              </ode>
              <torsional>
                <ode/>
              </torsional>
            </friction>
            <bounce/>
          </surface>
          <max_contacts>10</max_contacts>
        </collision>
        <visual name='visual'>
          <cast_shadows>0</cast_shadows>
          <geometry>
            <plane>
              <normal>0 0 1</normal>
              <size>100 100</size>
            </plane>
          </geometry>
          <material>
            <script>
              <uri>file://media/materials/scripts/gazebo.material</uri>
              <name>Gazebo/Grey</name>
            </script>
          </material>
        </visual>
        <self_collide>0</self_collide>
        <enable_wind>0</enable_wind>
        <kinematic>0</kinematic>
      </link>
    </model>
    <gravity>0 0 -9.8</gravity>
    <magnetic_field>6e-06 2.3e-05 -4.2e-05</magnetic_field>
    <atmosphere type='adiabatic'/>
    <physics name='default_physics' default='0' type='ode'>
      <max_step_size>0.001</max_step_size>
      <real_time_factor>1</real_time_factor>
      <real_time_update_rate>1000</real_time_update_rate>
    </physics>
    <scene>
      <ambient>0.4 0.4 0.4 1</ambient>
      <background>0.7 0.7 0.7 1</background>
      <shadows>1</shadows>
    </scene>
    <wind/>
    <spherical_coordinates>
      <surface_model>EARTH_WGS84</surface_model>
      <latitude_deg>0</latitude_deg>
      <longitude_deg>0</longitude_deg>
      <elevation>0</elevation>
      <heading_deg>0</heading_deg>
    </spherical_coordinates>
    <model name='husarion-flat'>
      <pose frame=''>-14.4892 -4.94776 0 0 -0 0</pose>
      <link name='Wall_0'>
        <collision name='Wall_0_Collision'>
          <geometry>
            <box>
              <size>21.25 0.15 2.5</size>
            </box>
          </geometry>
          <pose frame=''>0 0 1.25 0 -0 0</pose>
          <max_contacts>10</max_contacts>
          <surface>
            <contact>
              <ode/>
            </contact>
            <bounce/>
            <friction>
              <torsional>
                <ode/>
              </torsional>
              <ode/>
            </friction>
          </surface>
        </collision>
        <visual name='Wall_0_Visual'>
          <pose frame=''>0 0 1.25 0 -0 0</pose>
          <geometry>
            <box>
              <size>21.25 0.15 2.5</size>
            </box>
          </geometry>
          <material>
            <script>
              <uri>file://media/materials/scripts/gazebo.material</uri>
              <name>Gazebo/Grey</name>
            </script>
            <ambient>0.921569 0.807843 0.615686 1</ambient>
          </material>
          <meta>
            <layer>0</layer>
          </meta>
        </visual>
        <pose frame=''>1.58584 -6.58294 0 0 -0 0</pose>
        <self_collide>0</self_collide>
        <enable_wind>0</enable_wind>
        <kinematic>0</kinematic>
      </link>
      <link name='Wall_1'>
        <pose frame=''>12.1358 -0.032942 0 0 -0 1.5708</pose>
        <visual name='Wall_1_Visual_0'>
          <pose frame=''>-4.56348 0 1.25 0 -0 0</pose>
          <geometry>
            <box>
              <size>4.12303 0.15 2.5</size>
            </box>
          </geometry>
          <material>
            <script>
              <uri>file://media/materials/scripts/gazebo.material</uri>
              <name>Gazebo/Grey</name>
            </script>
            <ambient>0.921569 0.807843 0.615686 1</ambient>
          </material>
          <meta>
            <layer>0</layer>
          </meta>
        </visual>
        <collision name='Wall_1_Collision_0'>
          <geometry>
            <box>
              <size>4.12303 0.15 2.5</size>
            </box>
          </geometry>
          <pose frame=''>-4.56348 0 1.25 0 -0 0</pose>
          <max_contacts>10</max_contacts>
          <surface>
            <contact>
              <ode/>
            </contact>
            <bounce/>
            <friction>
              <torsional>
                <ode/>
              </torsional>
              <ode/>
            </friction>
          </surface>
        </collision>
        <visual name='Wall_1_Visual_1'>
          <pose frame=''>2.06152 0 0.25 0 -0 0</pose>
          <geometry>
            <box>
              <size>9.12697 0.15 0.5</size>
            </box>
          </geometry>
          <material>
            <script>
              <uri>file://media/materials/scripts/gazebo.material</uri>
              <name>Gazebo/Grey</name>
            </script>
            <ambient>0.921569 0.807843 0.615686 1</ambient>
          </material>
          <meta>
            <layer>0</layer>
          </meta>
        </visual>
        <collision name='Wall_1_Collision_1'>
          <geometry>
            <box>
              <size>9.12697 0.15 0.5</size>
            </box>
          </geometry>
          <pose frame=''>2.06152 0 0.25 0 -0 0</pose>
          <max_contacts>10</max_contacts>
          <surface>
            <contact>
              <ode/>
            </contact>
            <bounce/>
            <friction>
              <torsional>
                <ode/>
              </torsional>
              <ode/>
            </friction>
          </surface>
        </collision>
        <visual name='Wall_1_Visual_2'>
          <pose frame=''>2.46152 0 1.5 0 -0 0</pose>
          <geometry>
            <box>
              <size>8.32696 0.15 2</size>
            </box>
          </geometry>
          <material>
            <script>
              <uri>file://media/materials/scripts/gazebo.material</uri>
              <name>Gazebo/Grey</name>
            </script>
            <ambient>0.921569 0.807843 0.615686 1</ambient>
          </material>
          <meta>
            <layer>0</layer>
          </meta>
        </visual>
        <collision name='Wall_1_Collision_2'>
          <geometry>
            <box>
              <size>8.32696 0.15 2</size>
            </box>
          </geometry>
          <pose frame=''>2.46152 0 1.5 0 -0 0</pose>
          <max_contacts>10</max_contacts>
          <surface>
            <contact>
              <ode/>
            </contact>
            <bounce/>
            <friction>
              <torsional>
                <ode/>
              </torsional>
              <ode/>
            </friction>
          </surface>
        </collision>
        <visual name='Wall_1_Visual_3'>
          <pose frame=''>-2.10196 0 1.9 0 -0 0</pose>
          <geometry>
            <box>
              <size>0.8 0.15 1.2</size>
            </box>
          </geometry>
          <material>
            <script>
              <uri>file://media/materials/scripts/gazebo.material</uri>
              <name>Gazebo/Grey</name>
            </script>
            <ambient>0.921569 0.807843 0.615686 1</ambient>
          </material>
          <meta>
            <layer>0</layer>
          </meta>
        </visual>
        <collision name='Wall_1_Collision_3'>
          <geometry>
            <box>
              <size>0.8 0.15 1.2</size>
            </box>
          </geometry>
          <pose frame=''>-2.10196 0 1.9 0 -0 0</pose>
          <max_contacts>10</max_contacts>
          <surface>
            <contact>
              <ode/>
            </contact>
            <bounce/>
            <friction>
              <torsional>
                <ode/>
              </torsional>
              <ode/>
            </friction>
          </surface>
        </collision>
        <self_collide>0</self_collide>
        <enable_wind>0</enable_wind>
        <kinematic>0</kinematic>
      </link>
      <link name='Wall_11'>
        <collision name='Wall_11_Collision'>
          <geometry>
            <box>
              <size>3.5 0.15 2.5</size>
            </box>
          </geometry>
          <pose frame=''>0 0 1.25 0 -0 0</pose>
          <max_contacts>10</max_contacts>
          <surface>
            <contact>
              <ode/>
            </contact>
            <bounce/>
            <friction>
              <torsional>
                <ode/>
              </torsional>
              <ode/>
            </friction>
          </surface>
        </collision>
        <visual name='Wall_11_Visual'>
          <pose frame=''>0 0 1.25 0 -0 0</pose>
          <geometry>
            <box>
              <size>3.5 0.15 2.5</size>
            </box>
          </geometry>
          <material>
            <script>
              <uri>file://media/materials/scripts/gazebo.material</uri>
              <name>Gazebo/Grey</name>
            </script>
            <ambient>0.921569 0.807843 0.615686 1</ambient>
          </material>
          <meta>
            <layer>0</layer>
          </meta>
        </visual>
        <pose frame=''>-9.8951 -4.85934 0 0 -0 -1.5708</pose>
        <self_collide>0</self_collide>
        <enable_wind>0</enable_wind>
        <kinematic>0</kinematic>
      </link>
      <link name='Wall_13'>
        <collision name='Wall_13_Collision'>
          <geometry>
            <box>
              <size>1.37236 0.15 2.5</size>
            </box>
          </geometry>
          <pose frame=''>0 0 1.25 0 -0 0</pose>
          <max_contacts>10</max_contacts>
          <surface>
            <contact>
              <ode/>
            </contact>
            <bounce/>
            <friction>
              <torsional>
                <ode/>
              </torsional>
              <ode/>
            </friction>
          </surface>
        </collision>
        <visual name='Wall_13_Visual'>
          <pose frame=''>0 0 1.25 0 -0 0</pose>
          <geometry>
            <box>
              <size>1.37236 0.15 2.5</size>
            </box>
          </geometry>
          <material>
            <script>
              <uri>file://media/materials/scripts/gazebo.material</uri>
              <name>Gazebo/Grey</name>
            </script>
            <ambient>0.921569 0.807843 0.615686 1</ambient>
          </material>
          <meta>
            <layer>0</layer>
          </meta>
        </visual>
        <pose frame=''>-9.28392 -3.18434 0 0 -0 0</pose>
        <self_collide>0</self_collide>
        <enable_wind>0</enable_wind>
        <kinematic>0</kinematic>
      </link>
      <link name='Wall_16'>
        <collision name='Wall_16_Collision'>
          <geometry>
            <box>
              <size>9.12764 0.15 2.5</size>
            </box>
          </geometry>
          <pose frame=''>0 0 1.25 0 -0 0</pose>
          <max_contacts>10</max_contacts>
          <surface>
            <contact>
              <ode/>
            </contact>
            <bounce/>
            <friction>
              <torsional>
                <ode/>
              </torsional>
              <ode/>
            </friction>
          </surface>
        </collision>
        <visual name='Wall_16_Visual'>
          <pose frame=''>0 0 1.25 0 -0 0</pose>
          <geometry>
            <box>
              <size>9.12764 0.15 2.5</size>
            </box>
          </geometry>
          <material>
            <script>
              <uri>file://media/materials/scripts/gazebo.material</uri>
              <name>Gazebo/Grey</name>
            </script>
            <ambient>0.921569 0.807843 0.615686 1</ambient>
          </material>
          <meta>
            <layer>0</layer>
          </meta>
        </visual>
        <pose frame=''>-4.18392 -3.18434 0 0 -0 0</pose>
        <self_collide>0</self_collide>
        <enable_wind>0</enable_wind>
        <kinematic>0</kinematic>
      </link>
      <link name='Wall_18'>
        <collision name='Wall_18_Collision'>
          <geometry>
            <box>
              <size>3.25 0.15 2.5</size>
            </box>
          </geometry>
          <pose frame=''>0 0 1.25 0 -0 0</pose>
          <max_contacts>10</max_contacts>
          <surface>
            <contact>
              <ode/>
            </contact>
            <bounce/>
            <friction>
              <torsional>
                <ode/>
              </torsional>
              <ode/>
            </friction>
          </surface>
        </collision>
        <visual name='Wall_18_Visual'>
          <pose frame=''>0 0 1.25 0 -0 0</pose>
          <geometry>
            <box>
              <size>3.25 0.15 2.5</size>
            </box>
          </geometry>
          <material>
            <script>
              <uri>file://media/materials/scripts/gazebo.material</uri>
              <name>Gazebo/Grey</name>
            </script>
            <ambient>0.921569 0.807843 0.615686 1</ambient>
          </material>
          <meta>
            <layer>0</layer>
          </meta>
        </visual>
        <pose frame=''>3.37433 -4.9517 0 0 -0 1.5708</pose>
        <self_collide>0</self_collide>
        <enable_wind>0</enable_wind>
        <kinematic>0</kinematic>
      </link>
      <link name='Wall_19'>
        <collision name='Wall_19_Collision'>
          <geometry>
            <box>
              <size>3.5 0.15 2.5</size>
            </box>
          </geometry>
          <pose frame=''>0 0 1.25 0 -0 0</pose>
          <max_contacts>10</max_contacts>
          <surface>
            <contact>
              <ode/>
            </contact>
            <bounce/>
            <friction>
              <torsional>
                <ode/>
              </torsional>
              <ode/>
            </friction>
          </surface>
        </collision>
        <visual name='Wall_19_Visual'>
          <pose frame=''>0 0 1.25 0 -0 0</pose>
          <geometry>
            <box>
              <size>3.5 0.15 2.5</size>
            </box>
          </geometry>
          <material>
            <script>
              <uri>file://media/materials/scripts/gazebo.material</uri>
              <name>Gazebo/Grey</name>
            </script>
            <ambient>0.921569 0.807843 0.615686 1</ambient>
          </material>
          <meta>
            <layer>0</layer>
          </meta>
        </visual>
        <pose frame=''>5.04933 -3.4017 0 0 -0 0</pose>
        <self_collide>0</self_collide>
        <enable_wind>0</enable_wind>
        <kinematic>0</kinematic>
      </link>
      <link name='Wall_2'>
        <pose frame=''>1.71084 6.51706 0 0 -0 3.14159</pose>
        <visual name='Wall_2_Visual_0'>
          <pose frame=''>-2.94842 0 1.25 0 -0 0</pose>
          <geometry>
            <box>
              <size>15.1032 0.15 2.5</size>
            </box>
          </geometry>
          <material>
            <script>
              <uri>file://media/materials/scripts/gazebo.material</uri>
              <name>Gazebo/Grey</name>
            </script>
            <ambient>0.921569 0.807843 0.615686 1</ambient>
          </material>
          <meta>
            <layer>0</layer>
          </meta>
        </visual>
        <collision name='Wall_2_Collision_0'>
          <geometry>
            <box>
              <size>15.1032 0.15 2.5</size>
            </box>
          </geometry>
          <pose frame=''>-2.94842 0 1.25 0 -0 0</pose>
          <max_contacts>10</max_contacts>
          <surface>
            <contact>
              <ode/>
            </contact>
            <bounce/>
            <friction>
              <torsional>
                <ode/>
              </torsional>
              <ode/>
            </friction>
          </surface>
        </collision>
        <visual name='Wall_2_Visual_1'>
          <pose frame=''>7.55158 0 0.25 0 -0 0</pose>
          <geometry>
            <box>
              <size>5.89684 0.15 0.5</size>
            </box>
          </geometry>
          <material>
            <script>
              <uri>file://media/materials/scripts/gazebo.material</uri>
              <name>Gazebo/Grey</name>
            </script>
            <ambient>0.921569 0.807843 0.615686 1</ambient>
          </material>
          <meta>
            <layer>0</layer>
          </meta>
        </visual>
        <collision name='Wall_2_Collision_1'>
          <geometry>
            <box>
              <size>5.89684 0.15 0.5</size>
            </box>
          </geometry>
          <pose frame=''>7.55158 0 0.25 0 -0 0</pose>
          <max_contacts>10</max_contacts>
          <surface>
            <contact>
              <ode/>
            </contact>
            <bounce/>
            <friction>
              <torsional>
                <ode/>
              </torsional>
              <ode/>
            </friction>
          </surface>
        </collision>
        <visual name='Wall_2_Visual_2'>
          <pose frame=''>7.95158 0 1.5 0 -0 0</pose>
          <geometry>
            <box>
              <size>5.09684 0.15 2</size>
            </box>
          </geometry>
          <material>
            <script>
              <uri>file://media/materials/scripts/gazebo.material</uri>
              <name>Gazebo/Grey</name>
            </script>
            <ambient>0.921569 0.807843 0.615686 1</ambient>
          </material>
          <meta>
            <layer>0</layer>
          </meta>
        </visual>
        <collision name='Wall_2_Collision_2'>
          <geometry>
            <box>
              <size>5.09684 0.15 2</size>
            </box>
          </geometry>
          <pose frame=''>7.95158 0 1.5 0 -0 0</pose>
          <max_contacts>10</max_contacts>
          <surface>
            <contact>
              <ode/>
            </contact>
            <bounce/>
            <friction>
              <torsional>
                <ode/>
              </torsional>
              <ode/>
            </friction>
          </surface>
        </collision>
        <visual name='Wall_2_Visual_3'>
          <pose frame=''>5.00316 0 1.9 0 -0 0</pose>
          <geometry>
            <box>
              <size>0.8 0.15 1.2</size>
            </box>
          </geometry>
          <material>
            <script>
              <uri>file://media/materials/scripts/gazebo.material</uri>
              <name>Gazebo/Grey</name>
            </script>
            <ambient>0.921569 0.807843 0.615686 1</ambient>
          </material>
          <meta>
            <layer>0</layer>
          </meta>
        </visual>
        <collision name='Wall_2_Collision_3'>
          <geometry>
            <box>
              <size>0.8 0.15 1.2</size>
            </box>
          </geometry>
          <pose frame=''>5.00316 0 1.9 0 -0 0</pose>
          <max_contacts>10</max_contacts>
          <surface>
            <contact>
              <ode/>
            </contact>
            <bounce/>
            <friction>
              <torsional>
                <ode/>
              </torsional>
              <ode/>
            </friction>
          </surface>
        </collision>
        <self_collide>0</self_collide>
        <enable_wind>0</enable_wind>
        <kinematic>0</kinematic>
      </link>
      <link name='Wall_21'>
        <collision name='Wall_21_Collision'>
          <geometry>
            <box>
              <size>3.25 0.15 2.5</size>
            </box>
          </geometry>
          <pose frame=''>0 0 1.25 0 -0 0</pose>
          <max_contacts>10</max_contacts>
          <surface>
            <contact>
              <ode/>
            </contact>
            <bounce/>
            <friction>
              <torsional>
                <ode/>
              </torsional>
              <ode/>
            </friction>
          </surface>
        </collision>
        <visual name='Wall_21_Visual'>
          <pose frame=''>0 0 1.25 0 -0 0</pose>
          <geometry>
            <box>
              <size>3.25 0.15 2.5</size>
            </box>
          </geometry>
          <material>
            <script>
              <uri>file://media/materials/scripts/gazebo.material</uri>
              <name>Gazebo/Grey</name>
            </script>
            <ambient>0.921569 0.807843 0.615686 1</ambient>
          </material>
          <meta>
            <layer>0</layer>
          </meta>
        </visual>
        <pose frame=''>10.6436 -3.34617 0 0 -0 3.14159</pose>
        <self_collide>0</self_collide>
        <enable_wind>0</enable_wind>
        <kinematic>0</kinematic>
      </link>
      <link name='Wall_23'>
        <collision name='Wall_23_Collision'>
          <geometry>
            <box>
              <size>5 0.15 2.5</size>
            </box>
          </geometry>
          <pose frame=''>0 0 1.25 0 -0 0</pose>
          <max_contacts>10</max_contacts>
          <surface>
            <contact>
              <ode/>
            </contact>
            <bounce/>
            <friction>
              <torsional>
                <ode/>
              </torsional>
              <ode/>
            </friction>
          </surface>
        </collision>
        <visual name='Wall_23_Visual'>
          <pose frame=''>0 0 1.25 0 -0 0</pose>
          <geometry>
            <box>
              <size>5 0.15 2.5</size>
            </box>
          </geometry>
          <material>
            <script>
              <uri>file://media/materials/scripts/gazebo.material</uri>
              <name>Gazebo/Grey</name>
            </script>
            <ambient>0.921569 0.807843 0.615686 1</ambient>
          </material>
          <meta>
            <layer>0</layer>
          </meta>
        </visual>
        <pose frame=''>-6.28916 -0.832942 0 0 -0 0</pose>
        <self_collide>0</self_collide>
        <enable_wind>0</enable_wind>
        <kinematic>0</kinematic>
      </link>
      <link name='Wall_25'>
        <collision name='Wall_25_Collision'>
          <geometry>
            <box>
              <size>7.75 0.15 2.5</size>
            </box>
          </geometry>
          <pose frame=''>0 0 1.25 0 -0 0</pose>
          <max_contacts>10</max_contacts>
          <surface>
            <contact>
              <ode/>
            </contact>
            <bounce/>
            <friction>
              <torsional>
                <ode/>
              </torsional>
              <ode/>
            </friction>
          </surface>
        </collision>
        <visual name='Wall_25_Visual'>
          <pose frame=''>0 0 1.25 0 -0 0</pose>
          <geometry>
            <box>
              <size>7.75 0.15 2.5</size>
            </box>
          </geometry>
          <material>
            <script>
              <uri>file://media/materials/scripts/gazebo.material</uri>
              <name>Gazebo/Grey</name>
            </script>
            <ambient>0.921569 0.807843 0.615686 1</ambient>
          </material>
          <meta>
            <layer>0</layer>
          </meta>
        </visual>
        <pose frame=''>2.84558 -0.837919 0 0 -0 0</pose>
        <self_collide>0</self_collide>
        <enable_wind>0</enable_wind>
        <kinematic>0</kinematic>
      </link>
      <link name='Wall_27'>
        <collision name='Wall_27_Collision'>
          <geometry>
            <box>
              <size>3.25 0.15 2.5</size>
            </box>
          </geometry>
          <pose frame=''>0 0 1.25 0 -0 0</pose>
          <max_contacts>10</max_contacts>
          <surface>
            <contact>
              <ode/>
            </contact>
            <bounce/>
            <friction>
              <torsional>
                <ode/>
              </torsional>
              <ode/>
            </friction>
          </surface>
        </collision>
        <visual name='Wall_27_Visual'>
          <pose frame=''>0 0 1.25 0 -0 0</pose>
          <geometry>
            <box>
              <size>3.25 0.15 2.5</size>
            </box>
          </geometry>
          <material>
            <script>
              <uri>file://media/materials/scripts/gazebo.material</uri>
              <name>Gazebo/Grey</name>
            </script>
            <ambient>0.921569 0.807843 0.615686 1</ambient>
          </material>
          <meta>
            <layer>0</layer>
          </meta>
        </visual>
        <pose frame=''>10.6286 -0.837919 0 0 -0 0</pose>
        <self_collide>0</self_collide>
        <enable_wind>0</enable_wind>
        <kinematic>0</kinematic>
      </link>
      <link name='Wall_29'>
        <collision name='Wall_29_Collision'>
          <geometry>
            <box>
              <size>7.5 0.15 2.5</size>
            </box>
          </geometry>
          <pose frame=''>0 0 1.25 0 -0 0</pose>
          <max_contacts>10</max_contacts>
          <surface>
            <contact>
              <ode/>
            </contact>
            <bounce/>
            <friction>
              <torsional>
                <ode/>
              </torsional>
              <ode/>
            </friction>
          </surface>
        </collision>
        <visual name='Wall_29_Visual'>
          <pose frame=''>0 0 1.25 0 -0 0</pose>
          <geometry>
            <box>
              <size>7.5 0.15 2.5</size>
            </box>
          </geometry>
          <material>
            <script>
              <uri>file://media/materials/scripts/gazebo.material</uri>
              <name>Gazebo/Grey</name>
            </script>
            <ambient>0.921569 0.807843 0.615686 1</ambient>
          </material>
          <meta>
            <layer>0</layer>
          </meta>
        </visual>
        <pose frame=''>2.92932 2.90794 0 0 -0 -1.5708</pose>
        <self_collide>0</self_collide>
        <enable_wind>0</enable_wind>
        <kinematic>0</kinematic>
      </link>
      <link name='Wall_3'>
        <collision name='Wall_3_Collision'>
          <geometry>
            <box>
              <size>7.5 0.15 2.5</size>
            </box>
          </geometry>
          <pose frame=''>0 0 1.25 0 -0 0</pose>
          <max_contacts>10</max_contacts>
          <surface>
            <contact>
              <ode/>
            </contact>
            <bounce/>
            <friction>
              <torsional>
                <ode/>
              </torsional>
              <ode/>
            </friction>
          </surface>
        </collision>
        <visual name='Wall_3_Visual'>
          <pose frame=''>0 0 1.25 0 -0 0</pose>
          <geometry>
            <box>
              <size>7.5 0.15 2.5</size>
            </box>
          </geometry>
          <material>
            <script>
              <uri>file://media/materials/scripts/gazebo.material</uri>
              <name>Gazebo/Grey</name>
            </script>
            <ambient>0.921569 0.807843 0.615686 1</ambient>
          </material>
          <meta>
            <layer>0</layer>
          </meta>
        </visual>
        <pose frame=''>-8.71416 2.84206 0 0 -0 -1.5708</pose>
        <self_collide>0</self_collide>
        <enable_wind>0</enable_wind>
        <kinematic>0</kinematic>
      </link>
      <link name='Wall_31'>
        <collision name='Wall_31_Collision'>
          <geometry>
            <box>
              <size>1 0.15 2.5</size>
            </box>
          </geometry>
          <pose frame=''>0 0 1.25 0 -0 0</pose>
          <max_contacts>10</max_contacts>
          <surface>
            <contact>
              <ode/>
            </contact>
            <bounce/>
            <friction>
              <torsional>
                <ode/>
              </torsional>
              <ode/>
            </friction>
          </surface>
        </collision>
        <visual name='Wall_31_Visual'>
          <pose frame=''>0 0 1.25 0 -0 0</pose>
          <geometry>
            <box>
              <size>1 0.15 2.5</size>
            </box>
          </geometry>
          <material>
            <script>
              <uri>file://media/materials/scripts/gazebo.material</uri>
              <name>Gazebo/Grey</name>
            </script>
            <ambient>0.921569 0.807843 0.615686 1</ambient>
          </material>
          <meta>
            <layer>0</layer>
          </meta>
        </visual>
        <pose frame=''>2.91681 -3.30242 0 0 -0 3.14159</pose>
        <self_collide>0</self_collide>
        <enable_wind>0</enable_wind>
        <kinematic>0</kinematic>
      </link>
      <link name='Wall_4'>
        <collision name='Wall_4_Collision'>
          <geometry>
            <box>
              <size>1.25 0.15 2.5</size>
            </box>
          </geometry>
          <pose frame=''>0 0 1.25 0 -0 0</pose>
          <max_contacts>10</max_contacts>
          <surface>
            <contact>
              <ode/>
            </contact>
            <bounce/>
            <friction>
              <torsional>
                <ode/>
              </torsional>
              <ode/>
            </friction>
          </surface>
        </collision>
        <visual name='Wall_4_Visual'>
          <pose frame=''>0 0 1.25 0 -0 0</pose>
          <geometry>
            <box>
              <size>1.25 0.15 2.5</size>
            </box>
          </geometry>
          <material>
            <script>
              <uri>file://media/materials/scripts/gazebo.material</uri>
              <name>Gazebo/Grey</name>
            </script>
            <ambient>0.921569 0.807843 0.615686 1</ambient>
          </material>
          <meta>
            <layer>0</layer>
          </meta>
        </visual>
        <pose frame=''>-9.26416 -0.832942 0 0 -0 3.14159</pose>
        <self_collide>0</self_collide>
        <enable_wind>0</enable_wind>
        <kinematic>0</kinematic>
      </link>
      <link name='Wall_5'>
        <collision name='Wall_5_Collision'>
          <geometry>
            <box>
              <size>3.25 0.15 2.5</size>
            </box>
          </geometry>
          <pose frame=''>0 0 1.25 0 -0 0</pose>
          <max_contacts>10</max_contacts>
          <surface>
            <contact>
              <ode/>
            </contact>
            <bounce/>
            <friction>
              <torsional>
                <ode/>
              </torsional>
              <ode/>
            </friction>
          </surface>
        </collision>
        <visual name='Wall_5_Visual'>
          <pose frame=''>0 0 1.25 0 -0 0</pose>
          <geometry>
            <box>
              <size>3.25 0.15 2.5</size>
            </box>
          </geometry>
          <material>
            <script>
              <uri>file://media/materials/scripts/gazebo.material</uri>
              <name>Gazebo/Grey</name>
            </script>
            <ambient>0.921569 0.807843 0.615686 1</ambient>
          </material>
          <meta>
            <layer>0</layer>
          </meta>
        </visual>
        <pose frame=''>-9.81416 0.717058 0 0 -0 1.5708</pose>
        <self_collide>0</self_collide>
        <enable_wind>0</enable_wind>
        <kinematic>0</kinematic>
      </link>
      <link name='Wall_6'>
        <pose frame=''>-12.1142 2.26706 0 0 -0 3.14159</pose>
        <visual name='Wall_6_Visual_0'>
          <pose frame=''>-1.33225 0 1.25 0 -0 0</pose>
          <geometry>
            <box>
              <size>2.08551 0.15 2.5</size>
            </box>
          </geometry>
          <material>
            <script>
              <uri>file://media/materials/scripts/gazebo.material</uri>
              <name>Gazebo/Grey</name>
            </script>
            <ambient>0.921569 0.807843 0.615686 1</ambient>
          </material>
          <meta>
            <layer>0</layer>
          </meta>
        </visual>
        <collision name='Wall_6_Collision_0'>
          <geometry>
            <box>
              <size>2.08551 0.15 2.5</size>
            </box>
          </geometry>
          <pose frame=''>-1.33225 0 1.25 0 -0 0</pose>
          <max_contacts>10</max_contacts>
          <surface>
            <contact>
              <ode/>
            </contact>
            <bounce/>
            <friction>
              <torsional>
                <ode/>
              </torsional>
              <ode/>
            </friction>
          </surface>
        </collision>
        <visual name='Wall_6_Visual_1'>
          <pose frame=''>1.04275 0 0.25 0 -0 0</pose>
          <geometry>
            <box>
              <size>2.66449 0.15 0.5</size>
            </box>
          </geometry>
          <material>
            <script>
              <uri>file://media/materials/scripts/gazebo.material</uri>
              <name>Gazebo/Grey</name>
            </script>
            <ambient>0.921569 0.807843 0.615686 1</ambient>
          </material>
          <meta>
            <layer>0</layer>
          </meta>
        </visual>
        <collision name='Wall_6_Collision_1'>
          <geometry>
            <box>
              <size>2.66449 0.15 0.5</size>
            </box>
          </geometry>
          <pose frame=''>1.04275 0 0.25 0 -0 0</pose>
          <max_contacts>10</max_contacts>
          <surface>
            <contact>
              <ode/>
            </contact>
            <bounce/>
            <friction>
              <torsional>
                <ode/>
              </torsional>
              <ode/>
            </friction>
          </surface>
        </collision>
        <visual name='Wall_6_Visual_2'>
          <pose frame=''>1.44275 0 1.5 0 -0 0</pose>
          <geometry>
            <box>
              <size>1.86449 0.15 2</size>
            </box>
          </geometry>
          <material>
            <script>
              <uri>file://media/materials/scripts/gazebo.material</uri>
              <name>Gazebo/Grey</name>
            </script>
            <ambient>0.921569 0.807843 0.615686 1</ambient>
          </material>
          <meta>
            <layer>0</layer>
          </meta>
        </visual>
        <collision name='Wall_6_Collision_2'>
          <geometry>
            <box>
              <size>1.86449 0.15 2</size>
            </box>
          </geometry>
          <pose frame=''>1.44275 0 1.5 0 -0 0</pose>
          <max_contacts>10</max_contacts>
          <surface>
            <contact>
              <ode/>
            </contact>
            <bounce/>
            <friction>
              <torsional>
                <ode/>
              </torsional>
              <ode/>
            </friction>
          </surface>
        </collision>
        <visual name='Wall_6_Visual_3'>
          <pose frame=''>0.110506 0 1.9 0 -0 0</pose>
          <geometry>
            <box>
              <size>0.8 0.15 1.2</size>
            </box>
          </geometry>
          <material>
            <script>
              <uri>file://media/materials/scripts/gazebo.material</uri>
              <name>Gazebo/Grey</name>
            </script>
            <ambient>0.921569 0.807843 0.615686 1</ambient>
          </material>
          <meta>
            <layer>0</layer>
          </meta>
        </visual>
        <collision name='Wall_6_Collision_3'>
          <geometry>
            <box>
              <size>0.8 0.15 1.2</size>
            </box>
          </geometry>
          <pose frame=''>0.110506 0 1.9 0 -0 0</pose>
          <max_contacts>10</max_contacts>
          <surface>
            <contact>
              <ode/>
            </contact>
            <bounce/>
            <friction>
              <torsional>
                <ode/>
              </torsional>
              <ode/>
            </friction>
          </surface>
        </collision>
        <self_collide>0</self_collide>
        <enable_wind>0</enable_wind>
        <kinematic>0</kinematic>
      </link>
      <link name='Wall_7'>
        <collision name='Wall_7_Collision'>
          <geometry>
            <box>
              <size>9 0.15 2.5</size>
            </box>
          </geometry>
          <pose frame=''>0 0 1.25 0 -0 0</pose>
          <max_contacts>10</max_contacts>
          <surface>
            <contact>
              <ode/>
            </contact>
            <bounce/>
            <friction>
              <torsional>
                <ode/>
              </torsional>
              <ode/>
            </friction>
          </surface>
        </collision>
        <visual name='Wall_7_Visual'>
          <pose frame=''>0 0 1.25 0 -0 0</pose>
          <geometry>
            <box>
              <size>9 0.15 2.5</size>
            </box>
          </geometry>
          <material>
            <script>
              <uri>file://media/materials/scripts/gazebo.material</uri>
              <name>Gazebo/Grey</name>
            </script>
            <ambient>0.921569 0.807843 0.615686 1</ambient>
          </material>
          <meta>
            <layer>0</layer>
          </meta>
        </visual>
        <pose frame=''>-14.4142 -2.15794 0 0 -0 -1.5708</pose>
        <self_collide>0</self_collide>
        <enable_wind>0</enable_wind>
        <kinematic>0</kinematic>
      </link>
      <link name='Wall_8'>
        <collision name='Wall_8_Collision'>
          <geometry>
            <box>
              <size>5.6 0.15 2.5</size>
            </box>
          </geometry>
          <pose frame=''>0 0 1.25 0 -0 0</pose>
          <max_contacts>10</max_contacts>
          <surface>
            <contact>
              <ode/>
            </contact>
            <bounce/>
            <friction>
              <torsional>
                <ode/>
              </torsional>
              <ode/>
            </friction>
          </surface>
        </collision>
        <visual name='Wall_8_Visual'>
          <pose frame=''>0 0 1.25 0 -0 0</pose>
          <geometry>
            <box>
              <size>5.6 0.15 2.5</size>
            </box>
          </geometry>
          <material>
            <script>
              <uri>file://media/materials/scripts/gazebo.material</uri>
              <name>Gazebo/Grey</name>
            </script>
            <ambient>0.921569 0.807843 0.615686 1</ambient>
          </material>
          <meta>
            <layer>0</layer>
          </meta>
        </visual>
        <pose frame=''>-11.6892 -6.58294 0 0 -0 0</pose>
        <self_collide>0</self_collide>
        <enable_wind>0</enable_wind>
        <kinematic>0</kinematic>
      </link>
      <static>1</static>
    </model>
    <model name='ragdoll'>
      <pose frame=''>16.2687 2.73096 1.4 0 -0 0</pose>
      <link name='hip'>
        <inertial>
          <inertia>
            <ixx>0.1</ixx>
            <ixy>0</ixy>
            <ixz>0</ixz>
            <iyy>0.1</iyy>
            <iyz>0</iyz>
            <izz>0.1</izz>
          </inertia>
          <mass>10</mass>
          <pose frame=''>0 0 0 0 -0 0</pose>
        </inertial>
        <collision name='hip_geom'>
          <pose frame=''>0 0 0.125 0 -0 0</pose>
          <geometry>
            <box>
              <size>0.1 0.5 0.25</size>
            </box>
          </geometry>
          <surface>
            <friction>
              <ode>
                <mu>-1</mu>
                <mu2>-1</mu2>
                <fdir1>0 0 0</fdir1>
                <slip1>0</slip1>
                <slip2>0</slip2>
              </ode>
              <torsional>
                <ode/>
              </torsional>
            </friction>
            <bounce>
              <restitution_coefficient>0</restitution_coefficient>
              <threshold>100000</threshold>
            </bounce>
            <contact>
              <ode>
                <soft_cfm>0</soft_cfm>
                <soft_erp>0.2</soft_erp>
                <kp>1e+12</kp>
                <kd>1</kd>
                <max_vel>0</max_vel>
                <min_depth>0.001</min_depth>
              </ode>
            </contact>
          </surface>
          <laser_retro>0</laser_retro>
          <max_contacts>10</max_contacts>
        </collision>
        <visual name='hip_geom_visual'>
          <pose frame=''>0 0 0.125 0 -0 0</pose>
          <geometry>
            <box>
              <size>0.1 0.5 0.25</size>
            </box>
          </geometry>
          <cast_shadows>1</cast_shadows>
          <laser_retro>0</laser_retro>
          <transparency>0</transparency>
        </visual>
        <gravity>0</gravity>
        <self_collide>0</self_collide>
        <kinematic>0</kinematic>
        <enable_wind>0</enable_wind>
      </link>
      <link name='l_thigh_pan'>
        <pose frame=''>0 0.22 0 0 -0 0</pose>
        <inertial>
          <inertia>
            <ixx>0.01</ixx>
            <ixy>0</ixy>
            <ixz>0</ixz>
            <iyy>0.01</iyy>
            <iyz>0</iyz>
            <izz>0.01</izz>
          </inertia>
          <mass>1</mass>
          <pose frame=''>0 0 0 0 -0 0</pose>
        </inertial>
        <collision name='l_thigh_pan_geom'>
          <pose frame=''>0 0 -0.03 0 -0 0</pose>
          <geometry>
            <sphere>
              <radius>0.06</radius>
            </sphere>
          </geometry>
          <surface>
            <friction>
              <ode>
                <mu>-1</mu>
                <mu2>-1</mu2>
                <fdir1>0 0 0</fdir1>
                <slip1>0</slip1>
                <slip2>0</slip2>
              </ode>
              <torsional>
                <ode/>
              </torsional>
            </friction>
            <bounce>
              <restitution_coefficient>0</restitution_coefficient>
              <threshold>100000</threshold>
            </bounce>
            <contact>
              <ode>
                <soft_cfm>0</soft_cfm>
                <soft_erp>0.2</soft_erp>
                <kp>1e+12</kp>
                <kd>1</kd>
                <max_vel>0</max_vel>
                <min_depth>0.001</min_depth>
              </ode>
            </contact>
          </surface>
          <laser_retro>0</laser_retro>
          <max_contacts>10</max_contacts>
        </collision>
        <visual name='l_thigh_pan_geom_visual'>
          <pose frame=''>0 0 -0.03 0 -0 0</pose>
          <geometry>
            <sphere>
              <radius>0.06</radius>
            </sphere>
          </geometry>
          <cast_shadows>1</cast_shadows>
          <laser_retro>0</laser_retro>
          <transparency>0</transparency>
        </visual>
        <gravity>0</gravity>
        <self_collide>0</self_collide>
        <kinematic>0</kinematic>
        <enable_wind>0</enable_wind>
      </link>
      <link name='l_thigh_lift'>
        <pose frame=''>0 0.22 0 0 -0 0</pose>
        <inertial>
          <inertia>
            <ixx>0.05</ixx>
            <ixy>0</ixy>
            <ixz>0</ixz>
            <iyy>0.05</iyy>
            <iyz>0</iyz>
            <izz>0.05</izz>
          </inertia>
          <mass>5</mass>
          <pose frame=''>0 0 0 0 -0 0</pose>
        </inertial>
        <collision name='l_thigh_lift_geom'>
          <pose frame=''>0 0 -0.35 0 -0 0</pose>
          <geometry>
            <cylinder>
              <radius>0.06</radius>
              <length>0.7</length>
            </cylinder>
          </geometry>
          <surface>
            <friction>
              <ode>
                <mu>-1</mu>
                <mu2>-1</mu2>
                <fdir1>0 0 0</fdir1>
                <slip1>0</slip1>
                <slip2>0</slip2>
              </ode>
              <torsional>
                <ode/>
              </torsional>
            </friction>
            <bounce>
              <restitution_coefficient>0</restitution_coefficient>
              <threshold>100000</threshold>
            </bounce>
            <contact>
              <ode>
                <soft_cfm>0</soft_cfm>
                <soft_erp>0.2</soft_erp>
                <kp>1e+12</kp>
                <kd>1</kd>
                <max_vel>0</max_vel>
                <min_depth>0.001</min_depth>
              </ode>
            </contact>
          </surface>
          <laser_retro>0</laser_retro>
          <max_contacts>10</max_contacts>
        </collision>
        <visual name='l_thigh_lift_geom_visual'>
          <pose frame=''>0 0 -0.35 0 -0 0</pose>
          <geometry>
            <cylinder>
              <radius>0.06</radius>
              <length>0.7</length>
            </cylinder>
          </geometry>
          <cast_shadows>1</cast_shadows>
          <laser_retro>0</laser_retro>
          <transparency>0</transparency>
        </visual>
        <gravity>0</gravity>
        <self_collide>0</self_collide>
        <kinematic>0</kinematic>
        <enable_wind>0</enable_wind>
      </link>
      <link name='l_calf'>
        <pose frame=''>0 0.22 -0.7 0 -0 0</pose>
        <inertial>
          <inertia>
            <ixx>0.02</ixx>
            <ixy>0</ixy>
            <ixz>0</ixz>
            <iyy>0.02</iyy>
            <iyz>0</iyz>
            <izz>0.02</izz>
          </inertia>
          <mass>2</mass>
          <pose frame=''>0 0 0 0 -0 0</pose>
        </inertial>
        <collision name='l_calf_geom'>
          <pose frame=''>0 0 -0.3 0 -0 0</pose>
          <geometry>
            <cylinder>
              <radius>0.05</radius>
              <length>0.6</length>
            </cylinder>
          </geometry>
          <surface>
            <friction>
              <ode>
                <mu>-1</mu>
                <mu2>-1</mu2>
                <fdir1>0 0 0</fdir1>
                <slip1>0</slip1>
                <slip2>0</slip2>
              </ode>
              <torsional>
                <ode/>
              </torsional>
            </friction>
            <bounce>
              <restitution_coefficient>0</restitution_coefficient>
              <threshold>100000</threshold>
            </bounce>
            <contact>
              <ode>
                <soft_cfm>0</soft_cfm>
                <soft_erp>0.2</soft_erp>
                <kp>1e+12</kp>
                <kd>1</kd>
                <max_vel>0</max_vel>
                <min_depth>0.001</min_depth>
              </ode>
            </contact>
          </surface>
          <laser_retro>0</laser_retro>
          <max_contacts>10</max_contacts>
        </collision>
        <visual name='l_calf_geom_visual'>
          <pose frame=''>0 0 -0.3 0 -0 0</pose>
          <geometry>
            <cylinder>
              <radius>0.05</radius>
              <length>0.6</length>
            </cylinder>
          </geometry>
          <cast_shadows>1</cast_shadows>
          <laser_retro>0</laser_retro>
          <transparency>0</transparency>
        </visual>
        <gravity>0</gravity>
        <self_collide>0</self_collide>
        <kinematic>0</kinematic>
        <enable_wind>0</enable_wind>
      </link>
      <link name='l_ankle'>
        <pose frame=''>0 0.22 -1.325 0 -0 0</pose>
        <inertial>
          <inertia>
            <ixx>0.01</ixx>
            <ixy>0</ixy>
            <ixz>0</ixz>
            <iyy>0.01</iyy>
            <iyz>0</iyz>
            <izz>0.01</izz>
          </inertia>
          <mass>1</mass>
          <pose frame=''>0 0 0 0 -0 0</pose>
        </inertial>
        <collision name='l_ankle_geom'>
          <geometry>
            <sphere>
              <radius>0.05</radius>
            </sphere>
          </geometry>
          <surface>
            <friction>
              <ode>
                <mu>-1</mu>
                <mu2>-1</mu2>
                <fdir1>0 0 0</fdir1>
                <slip1>0</slip1>
                <slip2>0</slip2>
              </ode>
              <torsional>
                <ode/>
              </torsional>
            </friction>
            <bounce>
              <restitution_coefficient>0</restitution_coefficient>
              <threshold>100000</threshold>
            </bounce>
            <contact>
              <ode>
                <soft_cfm>0</soft_cfm>
                <soft_erp>0.2</soft_erp>
                <kp>1e+12</kp>
                <kd>1</kd>
                <max_vel>0</max_vel>
                <min_depth>0.001</min_depth>
              </ode>
            </contact>
          </surface>
          <laser_retro>0</laser_retro>
          <max_contacts>10</max_contacts>
        </collision>
        <visual name='l_ankle_geom_visual'>
          <geometry>
            <sphere>
              <radius>0.05</radius>
            </sphere>
          </geometry>
          <cast_shadows>1</cast_shadows>
          <laser_retro>0</laser_retro>
          <transparency>0</transparency>
        </visual>
        <gravity>0</gravity>
        <self_collide>0</self_collide>
        <kinematic>0</kinematic>
        <enable_wind>0</enable_wind>
      </link>
      <link name='l_foot'>
        <pose frame=''>0 0.22 -1.35 0 -0 0</pose>
        <inertial>
          <pose frame=''>0.1 0 0 0 -0 0</pose>
          <inertia>
            <ixx>0.01</ixx>
            <ixy>0</ixy>
            <ixz>0</ixz>
            <iyy>0.01</iyy>
            <iyz>0</iyz>
            <izz>0.01</izz>
          </inertia>
          <mass>1</mass>
        </inertial>
        <collision name='l_foot_geom'>
          <pose frame=''>0.1 0 -0.025 0 -0 0</pose>
          <geometry>
            <box>
              <size>0.2 0.03 0.05</size>
            </box>
          </geometry>
          <surface>
            <friction>
              <ode>
                <mu>-1</mu>
                <mu2>-1</mu2>
                <fdir1>0 0 0</fdir1>
                <slip1>0</slip1>
                <slip2>0</slip2>
              </ode>
              <torsional>
                <ode/>
              </torsional>
            </friction>
            <bounce>
              <restitution_coefficient>0</restitution_coefficient>
              <threshold>100000</threshold>
            </bounce>
            <contact>
              <ode>
                <soft_cfm>0</soft_cfm>
                <soft_erp>0.2</soft_erp>
                <kp>1e+12</kp>
                <kd>1</kd>
                <max_vel>0</max_vel>
                <min_depth>0.001</min_depth>
              </ode>
            </contact>
          </surface>
          <laser_retro>0</laser_retro>
          <max_contacts>10</max_contacts>
        </collision>
        <visual name='l_foot_geom_visual'>
          <pose frame=''>0.1 0 -0.025 0 -0 0</pose>
          <geometry>
            <box>
              <size>0.2 0.03 0.05</size>
            </box>
          </geometry>
          <cast_shadows>1</cast_shadows>
          <laser_retro>0</laser_retro>
          <transparency>0</transparency>
        </visual>
        <gravity>1</gravity>
        <self_collide>0</self_collide>
        <kinematic>0</kinematic>
        <enable_wind>0</enable_wind>
      </link>
      <link name='r_thigh_pan'>
        <pose frame=''>0 -0.22 0 0 -0 0</pose>
        <inertial>
          <inertia>
            <ixx>0.01</ixx>
            <ixy>0</ixy>
            <ixz>0</ixz>
            <iyy>0.01</iyy>
            <iyz>0</iyz>
            <izz>0.01</izz>
          </inertia>
          <mass>1</mass>
          <pose frame=''>0 0 0 0 -0 0</pose>
        </inertial>
        <collision name='r_thigh_pan_geom'>
          <pose frame=''>0 0 -0.03 0 -0 0</pose>
          <geometry>
            <sphere>
              <radius>0.06</radius>
            </sphere>
          </geometry>
          <surface>
            <friction>
              <ode>
                <mu>-1</mu>
                <mu2>-1</mu2>
                <fdir1>0 0 0</fdir1>
                <slip1>0</slip1>
                <slip2>0</slip2>
              </ode>
              <torsional>
                <ode/>
              </torsional>
            </friction>
            <bounce>
              <restitution_coefficient>0</restitution_coefficient>
              <threshold>100000</threshold>
            </bounce>
            <contact>
              <ode>
                <soft_cfm>0</soft_cfm>
                <soft_erp>0.2</soft_erp>
                <kp>1e+12</kp>
                <kd>1</kd>
                <max_vel>0</max_vel>
                <min_depth>0.001</min_depth>
              </ode>
            </contact>
          </surface>
          <laser_retro>0</laser_retro>
          <max_contacts>10</max_contacts>
        </collision>
        <visual name='r_thigh_pan_geom_visual'>
          <pose frame=''>0 0 -0.03 0 -0 0</pose>
          <geometry>
            <sphere>
              <radius>0.06</radius>
            </sphere>
          </geometry>
          <cast_shadows>1</cast_shadows>
          <laser_retro>0</laser_retro>
          <transparency>0</transparency>
        </visual>
        <gravity>0</gravity>
        <self_collide>0</self_collide>
        <kinematic>0</kinematic>
        <enable_wind>0</enable_wind>
      </link>
      <link name='r_thigh_lift'>
        <pose frame=''>0 -0.22 0 0 -0 0</pose>
        <inertial>
          <inertia>
            <ixx>0.05</ixx>
            <ixy>0</ixy>
            <ixz>0</ixz>
            <iyy>0.05</iyy>
            <iyz>0</iyz>
            <izz>0.05</izz>
          </inertia>
          <mass>5</mass>
          <pose frame=''>0 0 0 0 -0 0</pose>
        </inertial>
        <collision name='r_thigh_lift_geom'>
          <pose frame=''>0 0 -0.35 0 -0 0</pose>
          <geometry>
            <cylinder>
              <radius>0.06</radius>
              <length>0.7</length>
            </cylinder>
          </geometry>
          <surface>
            <friction>
              <ode>
                <mu>-1</mu>
                <mu2>-1</mu2>
                <fdir1>0 0 0</fdir1>
                <slip1>0</slip1>
                <slip2>0</slip2>
              </ode>
              <torsional>
                <ode/>
              </torsional>
            </friction>
            <bounce>
              <restitution_coefficient>0</restitution_coefficient>
              <threshold>100000</threshold>
            </bounce>
            <contact>
              <ode>
                <soft_cfm>0</soft_cfm>
                <soft_erp>0.2</soft_erp>
                <kp>1e+12</kp>
                <kd>1</kd>
                <max_vel>0</max_vel>
                <min_depth>0.001</min_depth>
              </ode>
            </contact>
          </surface>
          <laser_retro>0</laser_retro>
          <max_contacts>10</max_contacts>
        </collision>
        <visual name='r_thigh_lift_geom_visual'>
          <pose frame=''>0 0 -0.35 0 -0 0</pose>
          <geometry>
            <cylinder>
              <radius>0.06</radius>
              <length>0.7</length>
            </cylinder>
          </geometry>
          <cast_shadows>1</cast_shadows>
          <laser_retro>0</laser_retro>
          <transparency>0</transparency>
        </visual>
        <gravity>0</gravity>
        <self_collide>0</self_collide>
        <kinematic>0</kinematic>
        <enable_wind>0</enable_wind>
      </link>
      <link name='r_calf'>
        <pose frame=''>0 -0.22 -0.7 0 -0 0</pose>
        <inertial>
          <inertia>
            <ixx>0.02</ixx>
            <ixy>0</ixy>
            <ixz>0</ixz>
            <iyy>0.02</iyy>
            <iyz>0</iyz>
            <izz>0.02</izz>
          </inertia>
          <mass>2</mass>
          <pose frame=''>0 0 0 0 -0 0</pose>
        </inertial>
        <collision name='r_calf_geom'>
          <pose frame=''>0 0 -0.3 0 -0 0</pose>
          <geometry>
            <cylinder>
              <radius>0.05</radius>
              <length>0.6</length>
            </cylinder>
          </geometry>
          <surface>
            <friction>
              <ode>
                <mu>-1</mu>
                <mu2>-1</mu2>
                <fdir1>0 0 0</fdir1>
                <slip1>0</slip1>
                <slip2>0</slip2>
              </ode>
              <torsional>
                <ode/>
              </torsional>
            </friction>
            <bounce>
              <restitution_coefficient>0</restitution_coefficient>
              <threshold>100000</threshold>
            </bounce>
            <contact>
              <ode>
                <soft_cfm>0</soft_cfm>
                <soft_erp>0.2</soft_erp>
                <kp>1e+12</kp>
                <kd>1</kd>
                <max_vel>0</max_vel>
                <min_depth>0.001</min_depth>
              </ode>
            </contact>
          </surface>
          <laser_retro>0</laser_retro>
          <max_contacts>10</max_contacts>
        </collision>
        <visual name='r_calf_geom_visual'>
          <pose frame=''>0 0 -0.3 0 -0 0</pose>
          <geometry>
            <cylinder>
              <radius>0.05</radius>
              <length>0.6</length>
            </cylinder>
          </geometry>
          <cast_shadows>1</cast_shadows>
          <laser_retro>0</laser_retro>
          <transparency>0</transparency>
        </visual>
        <gravity>0</gravity>
        <self_collide>0</self_collide>
        <kinematic>0</kinematic>
        <enable_wind>0</enable_wind>
      </link>
      <link name='r_ankle'>
        <pose frame=''>0 -0.22 -1.325 0 -0 0</pose>
        <inertial>
          <inertia>
            <ixx>0.01</ixx>
            <ixy>0</ixy>
            <ixz>0</ixz>
            <iyy>0.01</iyy>
            <iyz>0</iyz>
            <izz>0.01</izz>
          </inertia>
          <mass>1</mass>
          <pose frame=''>0 0 0 0 -0 0</pose>
        </inertial>
        <collision name='r_ankle_geom'>
          <geometry>
            <sphere>
              <radius>0.05</radius>
            </sphere>
          </geometry>
          <surface>
            <friction>
              <ode>
                <mu>-1</mu>
                <mu2>-1</mu2>
                <fdir1>0 0 0</fdir1>
                <slip1>0</slip1>
                <slip2>0</slip2>
              </ode>
              <torsional>
                <ode/>
              </torsional>
            </friction>
            <bounce>
              <restitution_coefficient>0</restitution_coefficient>
              <threshold>100000</threshold>
            </bounce>
            <contact>
              <ode>
                <soft_cfm>0</soft_cfm>
                <soft_erp>0.2</soft_erp>
                <kp>1e+12</kp>
                <kd>1</kd>
                <max_vel>0</max_vel>
                <min_depth>0.001</min_depth>
              </ode>
            </contact>
          </surface>
          <laser_retro>0</laser_retro>
          <max_contacts>10</max_contacts>
        </collision>
        <visual name='r_ankle_geom_visual'>
          <geometry>
            <sphere>
              <radius>0.05</radius>
            </sphere>
          </geometry>
          <cast_shadows>1</cast_shadows>
          <laser_retro>0</laser_retro>
          <transparency>0</transparency>
        </visual>
        <gravity>0</gravity>
        <self_collide>0</self_collide>
        <kinematic>0</kinematic>
        <enable_wind>0</enable_wind>
      </link>
      <link name='r_foot'>
        <pose frame=''>0 -0.22 -1.35 0 -0 0</pose>
        <inertial>
          <pose frame=''>0.1 0 0 0 -0 0</pose>
          <inertia>
            <ixx>0.01</ixx>
            <ixy>0</ixy>
            <ixz>0</ixz>
            <iyy>0.01</iyy>
            <iyz>0</iyz>
            <izz>0.01</izz>
          </inertia>
          <mass>1</mass>
        </inertial>
        <collision name='r_foot_geom'>
          <pose frame=''>0.1 0 -0.025 0 -0 0</pose>
          <geometry>
            <box>
              <size>0.2 0.03 0.05</size>
            </box>
          </geometry>
          <surface>
            <friction>
              <ode>
                <mu>-1</mu>
                <mu2>-1</mu2>
                <fdir1>0 0 0</fdir1>
                <slip1>0</slip1>
                <slip2>0</slip2>
              </ode>
              <torsional>
                <ode/>
              </torsional>
            </friction>
            <bounce>
              <restitution_coefficient>0</restitution_coefficient>
              <threshold>100000</threshold>
            </bounce>
            <contact>
              <ode>
                <soft_cfm>0</soft_cfm>
                <soft_erp>0.2</soft_erp>
                <kp>1e+12</kp>
                <kd>1</kd>
                <max_vel>0</max_vel>
                <min_depth>0.001</min_depth>
              </ode>
            </contact>
          </surface>
          <laser_retro>0</laser_retro>
          <max_contacts>10</max_contacts>
        </collision>
        <visual name='r_foot_geom_visual'>
          <pose frame=''>0.1 0 -0.025 0 -0 0</pose>
          <geometry>
            <box>
              <size>0.2 0.03 0.05</size>
            </box>
          </geometry>
          <cast_shadows>1</cast_shadows>
          <laser_retro>0</laser_retro>
          <transparency>0</transparency>
        </visual>
        <gravity>1</gravity>
        <self_collide>0</self_collide>
        <kinematic>0</kinematic>
        <enable_wind>0</enable_wind>
      </link>
      <link name='torso'>
        <pose frame=''>0 0 0.25 0 -0 0</pose>
        <inertial>
          <inertia>
            <ixx>0.3</ixx>
            <ixy>0</ixy>
            <ixz>0</ixz>
            <iyy>0.3</iyy>
            <iyz>0</iyz>
            <izz>0.3</izz>
          </inertia>
          <mass>30</mass>
          <pose frame=''>0 0 0 0 -0 0</pose>
        </inertial>
        <collision name='torso_geom'>
          <pose frame=''>0 0 0.35 0 -0 0</pose>
          <geometry>
            <box>
              <size>0.1 0.6 0.7</size>
            </box>
          </geometry>
          <surface>
            <friction>
              <ode>
                <mu>-1</mu>
                <mu2>-1</mu2>
                <fdir1>0 0 0</fdir1>
                <slip1>0</slip1>
                <slip2>0</slip2>
              </ode>
              <torsional>
                <ode/>
              </torsional>
            </friction>
            <bounce>
              <restitution_coefficient>0</restitution_coefficient>
              <threshold>100000</threshold>
            </bounce>
            <contact>
              <ode>
                <soft_cfm>0</soft_cfm>
                <soft_erp>0.2</soft_erp>
                <kp>1e+12</kp>
                <kd>1</kd>
                <max_vel>0</max_vel>
                <min_depth>0.001</min_depth>
              </ode>
            </contact>
          </surface>
          <laser_retro>0</laser_retro>
          <max_contacts>10</max_contacts>
        </collision>
        <visual name='torso_geom_visual'>
          <pose frame=''>0 0 0.35 0 -0 0</pose>
          <geometry>
            <box>
              <size>0.1 0.6 0.7</size>
            </box>
          </geometry>
          <cast_shadows>1</cast_shadows>
          <laser_retro>0</laser_retro>
          <transparency>0</transparency>
        </visual>
        <gravity>0</gravity>
        <self_collide>0</self_collide>
        <kinematic>0</kinematic>
        <enable_wind>0</enable_wind>
      </link>
      <link name='l_shoulder'>
        <pose frame=''>0 0.3275 0.9225 0 -0 0</pose>
        <inertial>
          <inertia>
            <ixx>0.01</ixx>
            <ixy>0</ixy>
            <ixz>0</ixz>
            <iyy>0.01</iyy>
            <iyz>0</iyz>
            <izz>0.01</izz>
          </inertia>
          <mass>1</mass>
          <pose frame=''>0 0 0 0 -0 0</pose>
        </inertial>
        <collision name='l_shoulder_geom'>
          <geometry>
            <sphere>
              <radius>0.055</radius>
            </sphere>
          </geometry>
          <surface>
            <friction>
              <ode>
                <mu>-1</mu>
                <mu2>-1</mu2>
                <fdir1>0 0 0</fdir1>
                <slip1>0</slip1>
                <slip2>0</slip2>
              </ode>
              <torsional>
                <ode/>
              </torsional>
            </friction>
            <bounce>
              <restitution_coefficient>0</restitution_coefficient>
              <threshold>100000</threshold>
            </bounce>
            <contact>
              <ode>
                <soft_cfm>0</soft_cfm>
                <soft_erp>0.2</soft_erp>
                <kp>1e+12</kp>
                <kd>1</kd>
                <max_vel>0</max_vel>
                <min_depth>0.001</min_depth>
              </ode>
            </contact>
          </surface>
          <laser_retro>0</laser_retro>
          <max_contacts>10</max_contacts>
        </collision>
        <visual name='l_shoulder_geom_visual'>
          <geometry>
            <sphere>
              <radius>0.055</radius>
            </sphere>
          </geometry>
          <cast_shadows>1</cast_shadows>
          <laser_retro>0</laser_retro>
          <transparency>0</transparency>
        </visual>
        <gravity>0</gravity>
        <self_collide>0</self_collide>
        <kinematic>0</kinematic>
        <enable_wind>0</enable_wind>
      </link>
      <link name='l_upper_arm'>
        <pose frame=''>0 0.3275 0.9225 0 -0 0</pose>
        <inertial>
          <inertia>
            <ixx>0.02</ixx>
            <ixy>0</ixy>
            <ixz>0</ixz>
            <iyy>0.02</iyy>
            <iyz>0</iyz>
            <izz>0.02</izz>
          </inertia>
          <mass>2</mass>
          <pose frame=''>0 0 0 0 -0 0</pose>
        </inertial>
        <collision name='l_upper_arm_geom'>
          <pose frame=''>0 0 -0.3 0 -0 0</pose>
          <geometry>
            <cylinder>
              <radius>0.055</radius>
              <length>0.6</length>
            </cylinder>
          </geometry>
          <surface>
            <friction>
              <ode>
                <mu>-1</mu>
                <mu2>-1</mu2>
                <fdir1>0 0 0</fdir1>
                <slip1>0</slip1>
                <slip2>0</slip2>
              </ode>
              <torsional>
                <ode/>
              </torsional>
            </friction>
            <bounce>
              <restitution_coefficient>0</restitution_coefficient>
              <threshold>100000</threshold>
            </bounce>
            <contact>
              <ode>
                <soft_cfm>0</soft_cfm>
                <soft_erp>0.2</soft_erp>
                <kp>1e+12</kp>
                <kd>1</kd>
                <max_vel>0</max_vel>
                <min_depth>0.001</min_depth>
              </ode>
            </contact>
          </surface>
          <laser_retro>0</laser_retro>
          <max_contacts>10</max_contacts>
        </collision>
        <visual name='l_upper_arm_geom_visual'>
          <pose frame=''>0 0 -0.3 0 -0 0</pose>
          <geometry>
            <cylinder>
              <radius>0.055</radius>
              <length>0.6</length>
            </cylinder>
          </geometry>
          <cast_shadows>1</cast_shadows>
          <laser_retro>0</laser_retro>
          <transparency>0</transparency>
        </visual>
        <gravity>0</gravity>
        <self_collide>0</self_collide>
        <kinematic>0</kinematic>
        <enable_wind>0</enable_wind>
      </link>
      <link name='l_forearm'>
        <pose frame=''>0 0.3275 0.3225 0 -0 0</pose>
        <inertial>
          <inertia>
            <ixx>0.01</ixx>
            <ixy>0</ixy>
            <ixz>0</ixz>
            <iyy>0.01</iyy>
            <iyz>0</iyz>
            <izz>0.01</izz>
          </inertia>
          <mass>1</mass>
          <pose frame=''>0 0 0 0 -0 0</pose>
        </inertial>
        <collision name='l_forearm_geom'>
          <pose frame=''>0 0 -0.225 0 -0 0</pose>
          <geometry>
            <cylinder>
              <radius>0.05</radius>
              <length>0.45</length>
            </cylinder>
          </geometry>
          <surface>
            <friction>
              <ode>
                <mu>-1</mu>
                <mu2>-1</mu2>
                <fdir1>0 0 0</fdir1>
                <slip1>0</slip1>
                <slip2>0</slip2>
              </ode>
              <torsional>
                <ode/>
              </torsional>
            </friction>
            <bounce>
              <restitution_coefficient>0</restitution_coefficient>
              <threshold>100000</threshold>
            </bounce>
            <contact>
              <ode>
                <soft_cfm>0</soft_cfm>
                <soft_erp>0.2</soft_erp>
                <kp>1e+12</kp>
                <kd>1</kd>
                <max_vel>0</max_vel>
                <min_depth>0.001</min_depth>
              </ode>
            </contact>
          </surface>
          <laser_retro>0</laser_retro>
          <max_contacts>10</max_contacts>
        </collision>
        <visual name='l_forearm_geom_visual'>
          <pose frame=''>0 0 -0.225 0 -0 0</pose>
          <geometry>
            <cylinder>
              <radius>0.05</radius>
              <length>0.45</length>
            </cylinder>
          </geometry>
          <cast_shadows>1</cast_shadows>
          <laser_retro>0</laser_retro>
          <transparency>0</transparency>
        </visual>
        <gravity>0</gravity>
        <self_collide>0</self_collide>
        <kinematic>0</kinematic>
        <enable_wind>0</enable_wind>
      </link>
      <link name='l_wrist'>
        <pose frame=''>0 0.3275 -0.1425 0 -0 0</pose>
        <inertial>
          <inertia>
            <ixx>0.01</ixx>
            <ixy>0</ixy>
            <ixz>0</ixz>
            <iyy>0.01</iyy>
            <iyz>0</iyz>
            <izz>0.01</izz>
          </inertia>
          <mass>1</mass>
          <pose frame=''>0 0 0 0 -0 0</pose>
        </inertial>
        <collision name='l_wrist_geom'>
          <geometry>
            <sphere>
              <radius>0.03</radius>
            </sphere>
          </geometry>
          <surface>
            <friction>
              <ode>
                <mu>-1</mu>
                <mu2>-1</mu2>
                <fdir1>0 0 0</fdir1>
                <slip1>0</slip1>
                <slip2>0</slip2>
              </ode>
              <torsional>
                <ode/>
              </torsional>
            </friction>
            <bounce>
              <restitution_coefficient>0</restitution_coefficient>
              <threshold>100000</threshold>
            </bounce>
            <contact>
              <ode>
                <soft_cfm>0</soft_cfm>
                <soft_erp>0.2</soft_erp>
                <kp>1e+12</kp>
                <kd>1</kd>
                <max_vel>0</max_vel>
                <min_depth>0.001</min_depth>
              </ode>
            </contact>
          </surface>
          <laser_retro>0</laser_retro>
          <max_contacts>10</max_contacts>
        </collision>
        <visual name='l_wrist_geom_visual'>
          <geometry>
            <sphere>
              <radius>0.03</radius>
            </sphere>
          </geometry>
          <cast_shadows>1</cast_shadows>
          <laser_retro>0</laser_retro>
          <transparency>0</transparency>
        </visual>
        <gravity>0</gravity>
        <self_collide>0</self_collide>
        <kinematic>0</kinematic>
        <enable_wind>0</enable_wind>
      </link>
      <link name='l_hand'>
        <pose frame=''>0 0.3275 -0.1575 0 -0 0</pose>
        <inertial>
          <inertia>
            <ixx>0.01</ixx>
            <ixy>0</ixy>
            <ixz>0</ixz>
            <iyy>0.01</iyy>
            <iyz>0</iyz>
            <izz>0.01</izz>
          </inertia>
          <mass>1</mass>
          <pose frame=''>0 0 0 0 -0 0</pose>
        </inertial>
        <collision name='l_hand_geom'>
          <pose frame=''>0 0 -0.1 0 -0 0</pose>
          <geometry>
            <box>
              <size>0.03 0.1 0.2</size>
            </box>
          </geometry>
          <surface>
            <friction>
              <ode>
                <mu>-1</mu>
                <mu2>-1</mu2>
                <fdir1>0 0 0</fdir1>
                <slip1>0</slip1>
                <slip2>0</slip2>
              </ode>
              <torsional>
                <ode/>
              </torsional>
            </friction>
            <bounce>
              <restitution_coefficient>0</restitution_coefficient>
              <threshold>100000</threshold>
            </bounce>
            <contact>
              <ode>
                <soft_cfm>0</soft_cfm>
                <soft_erp>0.2</soft_erp>
                <kp>1e+12</kp>
                <kd>1</kd>
                <max_vel>0</max_vel>
                <min_depth>0.001</min_depth>
              </ode>
            </contact>
          </surface>
          <laser_retro>0</laser_retro>
          <max_contacts>10</max_contacts>
        </collision>
        <visual name='l_hand_geom_visual'>
          <pose frame=''>0 0 -0.1 0 -0 0</pose>
          <geometry>
            <box>
              <size>0.03 0.1 0.2</size>
            </box>
          </geometry>
          <cast_shadows>1</cast_shadows>
          <laser_retro>0</laser_retro>
          <transparency>0</transparency>
        </visual>
        <gravity>0</gravity>
        <self_collide>0</self_collide>
        <kinematic>0</kinematic>
        <enable_wind>0</enable_wind>
      </link>
      <link name='neck'>
        <pose frame=''>0 0 0.95 0 -0 0</pose>
        <inertial>
          <inertia>
            <ixx>0.01</ixx>
            <ixy>0</ixy>
            <ixz>0</ixz>
            <iyy>0.01</iyy>
            <iyz>0</iyz>
            <izz>0.01</izz>
          </inertia>
          <mass>1</mass>
          <pose frame=''>0 0 0 0 -0 0</pose>
        </inertial>
        <collision name='neck_geom'>
          <pose frame=''>0 0 0.1 0 -0 0</pose>
          <geometry>
            <cylinder>
              <radius>0.075</radius>
              <length>0.2</length>
            </cylinder>
          </geometry>
          <surface>
            <friction>
              <ode>
                <mu>-1</mu>
                <mu2>-1</mu2>
                <fdir1>0 0 0</fdir1>
                <slip1>0</slip1>
                <slip2>0</slip2>
              </ode>
              <torsional>
                <ode/>
              </torsional>
            </friction>
            <bounce>
              <restitution_coefficient>0</restitution_coefficient>
              <threshold>100000</threshold>
            </bounce>
            <contact>
              <ode>
                <soft_cfm>0</soft_cfm>
                <soft_erp>0.2</soft_erp>
                <kp>1e+12</kp>
                <kd>1</kd>
                <max_vel>0</max_vel>
                <min_depth>0.001</min_depth>
              </ode>
            </contact>
          </surface>
          <laser_retro>0</laser_retro>
          <max_contacts>10</max_contacts>
        </collision>
        <visual name='neck_geom_visual'>
          <pose frame=''>0 0 0.1 0 -0 0</pose>
          <geometry>
            <cylinder>
              <radius>0.075</radius>
              <length>0.2</length>
            </cylinder>
          </geometry>
          <cast_shadows>1</cast_shadows>
          <laser_retro>0</laser_retro>
          <transparency>0</transparency>
        </visual>
        <gravity>0</gravity>
        <self_collide>0</self_collide>
        <kinematic>0</kinematic>
        <enable_wind>0</enable_wind>
      </link>
      <link name='head'>
        <pose frame=''>0 0 1.225 0 -0 0</pose>
        <inertial>
          <inertia>
            <ixx>0.1</ixx>
            <ixy>0</ixy>
            <ixz>0</ixz>
            <iyy>0.1</iyy>
            <iyz>0</iyz>
            <izz>0.1</izz>
          </inertia>
          <mass>10</mass>
          <pose frame=''>0 0 0 0 -0 0</pose>
        </inertial>
        <collision name='head_geom'>
          <geometry>
            <sphere>
              <radius>0.15</radius>
            </sphere>
          </geometry>
          <surface>
            <friction>
              <ode>
                <mu>-1</mu>
                <mu2>-1</mu2>
                <fdir1>0 0 0</fdir1>
                <slip1>0</slip1>
                <slip2>0</slip2>
              </ode>
              <torsional>
                <ode/>
              </torsional>
            </friction>
            <bounce>
              <restitution_coefficient>0</restitution_coefficient>
              <threshold>100000</threshold>
            </bounce>
            <contact>
              <ode>
                <soft_cfm>0</soft_cfm>
                <soft_erp>0.2</soft_erp>
                <kp>1e+12</kp>
                <kd>1</kd>
                <max_vel>0</max_vel>
                <min_depth>0.001</min_depth>
              </ode>
            </contact>
          </surface>
          <laser_retro>0</laser_retro>
          <max_contacts>10</max_contacts>
        </collision>
        <visual name='head_geom_visual'>
          <geometry>
            <sphere>
              <radius>0.15</radius>
            </sphere>
          </geometry>
          <cast_shadows>1</cast_shadows>
          <laser_retro>0</laser_retro>
          <transparency>0</transparency>
        </visual>
        <gravity>0</gravity>
        <self_collide>0</self_collide>
        <kinematic>0</kinematic>
        <enable_wind>0</enable_wind>
      </link>
      <link name='r_shoulder'>
        <pose frame=''>0 -0.3275 0.9225 0 -0 0</pose>
        <inertial>
          <inertia>
            <ixx>0.01</ixx>
            <ixy>0</ixy>
            <ixz>0</ixz>
            <iyy>0.01</iyy>
            <iyz>0</iyz>
            <izz>0.01</izz>
          </inertia>
          <mass>1</mass>
          <pose frame=''>0 0 0 0 -0 0</pose>
        </inertial>
        <collision name='r_shoulder_geom'>
          <geometry>
            <sphere>
              <radius>0.055</radius>
            </sphere>
          </geometry>
          <surface>
            <friction>
              <ode>
                <mu>-1</mu>
                <mu2>-1</mu2>
                <fdir1>0 0 0</fdir1>
                <slip1>0</slip1>
                <slip2>0</slip2>
              </ode>
              <torsional>
                <ode/>
              </torsional>
            </friction>
            <bounce>
              <restitution_coefficient>0</restitution_coefficient>
              <threshold>100000</threshold>
            </bounce>
            <contact>
              <ode>
                <soft_cfm>0</soft_cfm>
                <soft_erp>0.2</soft_erp>
                <kp>1e+12</kp>
                <kd>1</kd>
                <max_vel>0</max_vel>
                <min_depth>0.001</min_depth>
              </ode>
            </contact>
          </surface>
          <laser_retro>0</laser_retro>
          <max_contacts>10</max_contacts>
        </collision>
        <visual name='r_shoulder_geom_visual'>
          <geometry>
            <sphere>
              <radius>0.055</radius>
            </sphere>
          </geometry>
          <cast_shadows>1</cast_shadows>
          <laser_retro>0</laser_retro>
          <transparency>0</transparency>
        </visual>
        <gravity>0</gravity>
        <self_collide>0</self_collide>
        <kinematic>0</kinematic>
        <enable_wind>0</enable_wind>
      </link>
      <link name='r_upper_arm'>
        <pose frame=''>0 -0.3275 0.9225 0 -0 0</pose>
        <inertial>
          <inertia>
            <ixx>0.02</ixx>
            <ixy>0</ixy>
            <ixz>0</ixz>
            <iyy>0.02</iyy>
            <iyz>0</iyz>
            <izz>0.02</izz>
          </inertia>
          <mass>2</mass>
          <pose frame=''>0 0 0 0 -0 0</pose>
        </inertial>
        <collision name='r_upper_arm_geom'>
          <pose frame=''>0 0 -0.3 0 -0 0</pose>
          <geometry>
            <cylinder>
              <radius>0.055</radius>
              <length>0.6</length>
            </cylinder>
          </geometry>
          <surface>
            <friction>
              <ode>
                <mu>-1</mu>
                <mu2>-1</mu2>
                <fdir1>0 0 0</fdir1>
                <slip1>0</slip1>
                <slip2>0</slip2>
              </ode>
              <torsional>
                <ode/>
              </torsional>
            </friction>
            <bounce>
              <restitution_coefficient>0</restitution_coefficient>
              <threshold>100000</threshold>
            </bounce>
            <contact>
              <ode>
                <soft_cfm>0</soft_cfm>
                <soft_erp>0.2</soft_erp>
                <kp>1e+12</kp>
                <kd>1</kd>
                <max_vel>0</max_vel>
                <min_depth>0.001</min_depth>
              </ode>
            </contact>
          </surface>
          <laser_retro>0</laser_retro>
          <max_contacts>10</max_contacts>
        </collision>
        <visual name='r_upper_arm_geom_visual'>
          <pose frame=''>0 0 -0.3 0 -0 0</pose>
          <geometry>
            <cylinder>
              <radius>0.055</radius>
              <length>0.6</length>
            </cylinder>
          </geometry>
          <cast_shadows>1</cast_shadows>
          <laser_retro>0</laser_retro>
          <transparency>0</transparency>
        </visual>
        <gravity>0</gravity>
        <self_collide>0</self_collide>
        <kinematic>0</kinematic>
        <enable_wind>0</enable_wind>
      </link>
      <link name='r_forearm'>
        <pose frame=''>0 -0.3275 0.3225 0 -0 0</pose>
        <inertial>
          <inertia>
            <ixx>0.01</ixx>
            <ixy>0</ixy>
            <ixz>0</ixz>
            <iyy>0.01</iyy>
            <iyz>0</iyz>
            <izz>0.01</izz>
          </inertia>
          <mass>1</mass>
          <pose frame=''>0 0 0 0 -0 0</pose>
        </inertial>
        <collision name='r_forearm_geom'>
          <pose frame=''>0 0 -0.225 0 -0 0</pose>
          <geometry>
            <cylinder>
              <radius>0.05</radius>
              <length>0.45</length>
            </cylinder>
          </geometry>
          <surface>
            <friction>
              <ode>
                <mu>-1</mu>
                <mu2>-1</mu2>
                <fdir1>0 0 0</fdir1>
                <slip1>0</slip1>
                <slip2>0</slip2>
              </ode>
              <torsional>
                <ode/>
              </torsional>
            </friction>
            <bounce>
              <restitution_coefficient>0</restitution_coefficient>
              <threshold>100000</threshold>
            </bounce>
            <contact>
              <ode>
                <soft_cfm>0</soft_cfm>
                <soft_erp>0.2</soft_erp>
                <kp>1e+12</kp>
                <kd>1</kd>
                <max_vel>0</max_vel>
                <min_depth>0.001</min_depth>
              </ode>
            </contact>
          </surface>
          <laser_retro>0</laser_retro>
          <max_contacts>10</max_contacts>
        </collision>
        <visual name='r_forearm_geom_visual'>
          <pose frame=''>0 0 -0.225 0 -0 0</pose>
          <geometry>
            <cylinder>
              <radius>0.05</radius>
              <length>0.45</length>
            </cylinder>
          </geometry>
          <cast_shadows>1</cast_shadows>
          <laser_retro>0</laser_retro>
          <transparency>0</transparency>
        </visual>
        <gravity>0</gravity>
        <self_collide>0</self_collide>
        <kinematic>0</kinematic>
        <enable_wind>0</enable_wind>
      </link>
      <link name='r_wrist'>
        <pose frame=''>0 -0.3275 -0.1425 0 -0 0</pose>
        <inertial>
          <inertia>
            <ixx>0.01</ixx>
            <ixy>0</ixy>
            <ixz>0</ixz>
            <iyy>0.01</iyy>
            <iyz>0</iyz>
            <izz>0.01</izz>
          </inertia>
          <mass>1</mass>
          <pose frame=''>0 0 0 0 -0 0</pose>
        </inertial>
        <collision name='r_wrist_geom'>
          <geometry>
            <sphere>
              <radius>0.03</radius>
            </sphere>
          </geometry>
          <surface>
            <friction>
              <ode>
                <mu>-1</mu>
                <mu2>-1</mu2>
                <fdir1>0 0 0</fdir1>
                <slip1>0</slip1>
                <slip2>0</slip2>
              </ode>
              <torsional>
                <ode/>
              </torsional>
            </friction>
            <bounce>
              <restitution_coefficient>0</restitution_coefficient>
              <threshold>100000</threshold>
            </bounce>
            <contact>
              <ode>
                <soft_cfm>0</soft_cfm>
                <soft_erp>0.2</soft_erp>
                <kp>1e+12</kp>
                <kd>1</kd>
                <max_vel>0</max_vel>
                <min_depth>0.001</min_depth>
              </ode>
            </contact>
          </surface>
          <laser_retro>0</laser_retro>
          <max_contacts>10</max_contacts>
        </collision>
        <visual name='r_wrist_geom_visual'>
          <geometry>
            <sphere>
              <radius>0.03</radius>
            </sphere>
          </geometry>
          <cast_shadows>1</cast_shadows>
          <laser_retro>0</laser_retro>
          <transparency>0</transparency>
        </visual>
        <gravity>0</gravity>
        <self_collide>0</self_collide>
        <kinematic>0</kinematic>
        <enable_wind>0</enable_wind>
      </link>
      <link name='r_hand'>
        <pose frame=''>0 -0.3275 -0.1575 0 -0 0</pose>
        <inertial>
          <inertia>
            <ixx>0.01</ixx>
            <ixy>0</ixy>
            <ixz>0</ixz>
            <iyy>0.01</iyy>
            <iyz>0</iyz>
            <izz>0.01</izz>
          </inertia>
          <mass>1</mass>
          <pose frame=''>0 0 0 0 -0 0</pose>
        </inertial>
        <collision name='r_hand_geom'>
          <pose frame=''>0 0 -0.1 0 -0 0</pose>
          <geometry>
            <box>
              <size>0.03 0.1 0.2</size>
            </box>
          </geometry>
          <surface>
            <friction>
              <ode>
                <mu>-1</mu>
                <mu2>-1</mu2>
                <fdir1>0 0 0</fdir1>
                <slip1>0</slip1>
                <slip2>0</slip2>
              </ode>
              <torsional>
                <ode/>
              </torsional>
            </friction>
            <bounce>
              <restitution_coefficient>0</restitution_coefficient>
              <threshold>100000</threshold>
            </bounce>
            <contact>
              <ode>
                <soft_cfm>0</soft_cfm>
                <soft_erp>0.2</soft_erp>
                <kp>1e+12</kp>
                <kd>1</kd>
                <max_vel>0</max_vel>
                <min_depth>0.001</min_depth>
              </ode>
            </contact>
          </surface>
          <laser_retro>0</laser_retro>
          <max_contacts>10</max_contacts>
        </collision>
        <visual name='r_hand_geom_visual'>
          <pose frame=''>0 0 -0.1 0 -0 0</pose>
          <geometry>
            <box>
              <size>0.03 0.1 0.2</size>
            </box>
          </geometry>
          <cast_shadows>1</cast_shadows>
          <laser_retro>0</laser_retro>
          <transparency>0</transparency>
        </visual>
        <gravity>0</gravity>
        <self_collide>0</self_collide>
        <kinematic>0</kinematic>
        <enable_wind>0</enable_wind>
      </link>
      <joint name='l_thigh_pan_joint' type='revolute'>
        <parent>hip</parent>
        <child>l_thigh_pan</child>
        <axis>
          <dynamics>
            <damping>0</damping>
            <friction>0</friction>
            <spring_reference>0</spring_reference>
            <spring_stiffness>0</spring_stiffness>
          </dynamics>
          <limit>
            <lower>-1.5708</lower>
            <upper>1.5708</upper>
            <effort>0</effort>
            <velocity>0</velocity>
          </limit>
          <xyz>0 0 1</xyz>
          <use_parent_model_frame>1</use_parent_model_frame>
        </axis>
      </joint>
      <joint name='l_thigh_lift_joint' type='revolute'>
        <parent>l_thigh_pan</parent>
        <child>l_thigh_lift</child>
        <axis>
          <dynamics>
            <damping>0</damping>
            <friction>0</friction>
            <spring_reference>0</spring_reference>
            <spring_stiffness>0</spring_stiffness>
          </dynamics>
          <limit>
            <lower>-1.5708</lower>
            <upper>1.5708</upper>
            <effort>0</effort>
            <velocity>0</velocity>
          </limit>
          <xyz>0 1 0</xyz>
          <use_parent_model_frame>1</use_parent_model_frame>
        </axis>
      </joint>
      <joint name='l_calf_joint' type='revolute'>
        <parent>l_thigh_lift</parent>
        <child>l_calf</child>
        <axis>
          <dynamics>
            <damping>0</damping>
            <friction>0</friction>
            <spring_reference>0</spring_reference>
            <spring_stiffness>0</spring_stiffness>
          </dynamics>
          <limit>
            <lower>-1.5708</lower>
            <upper>1.5708</upper>
            <effort>0</effort>
            <velocity>0</velocity>
          </limit>
          <xyz>0 1 0</xyz>
          <use_parent_model_frame>1</use_parent_model_frame>
        </axis>
      </joint>
      <joint name='l_ankle_joint' type='revolute'>
        <parent>l_calf</parent>
        <child>l_ankle</child>
        <axis>
          <dynamics>
            <damping>0</damping>
            <friction>0</friction>
            <spring_reference>0</spring_reference>
            <spring_stiffness>0</spring_stiffness>
          </dynamics>
          <limit>
            <lower>-1.5708</lower>
            <upper>1.5708</upper>
            <effort>0</effort>
            <velocity>0</velocity>
          </limit>
          <xyz>0 1 0</xyz>
          <use_parent_model_frame>1</use_parent_model_frame>
        </axis>
      </joint>
      <joint name='l_foot_joint' type='revolute'>
        <parent>l_ankle</parent>
        <child>l_foot</child>
        <axis>
          <dynamics>
            <damping>0</damping>
            <friction>0</friction>
            <spring_reference>0</spring_reference>
            <spring_stiffness>0</spring_stiffness>
          </dynamics>
          <limit>
            <lower>-1.5708</lower>
            <upper>1.5708</upper>
            <effort>0</effort>
            <velocity>0</velocity>
          </limit>
          <xyz>1 0 0</xyz>
          <use_parent_model_frame>1</use_parent_model_frame>
        </axis>
      </joint>
      <joint name='r_thigh_pan_joint' type='revolute'>
        <parent>hip</parent>
        <child>r_thigh_pan</child>
        <axis>
          <dynamics>
            <damping>0</damping>
            <friction>0</friction>
            <spring_reference>0</spring_reference>
            <spring_stiffness>0</spring_stiffness>
          </dynamics>
          <limit>
            <lower>-1.5708</lower>
            <upper>1.5708</upper>
            <effort>0</effort>
            <velocity>0</velocity>
          </limit>
          <xyz>0 0 1</xyz>
          <use_parent_model_frame>1</use_parent_model_frame>
        </axis>
      </joint>
      <joint name='r_thigh_lift_joint' type='revolute'>
        <parent>r_thigh_pan</parent>
        <child>r_thigh_lift</child>
        <axis>
          <dynamics>
            <damping>0</damping>
            <friction>0</friction>
            <spring_reference>0</spring_reference>
            <spring_stiffness>0</spring_stiffness>
          </dynamics>
          <limit>
            <lower>-1.5708</lower>
            <upper>1.5708</upper>
            <effort>0</effort>
            <velocity>0</velocity>
          </limit>
          <xyz>0 1 0</xyz>
          <use_parent_model_frame>1</use_parent_model_frame>
        </axis>
      </joint>
      <joint name='r_calf_joint' type='revolute'>
        <parent>r_thigh_lift</parent>
        <child>r_calf</child>
        <axis>
          <dynamics>
            <damping>0</damping>
            <friction>0</friction>
            <spring_reference>0</spring_reference>
            <spring_stiffness>0</spring_stiffness>
          </dynamics>
          <limit>
            <lower>-1.5708</lower>
            <upper>1.5708</upper>
            <effort>0</effort>
            <velocity>0</velocity>
          </limit>
          <xyz>0 1 0</xyz>
          <use_parent_model_frame>1</use_parent_model_frame>
        </axis>
      </joint>
      <joint name='r_ankle_joint' type='revolute'>
        <parent>r_calf</parent>
        <child>r_ankle</child>
        <axis>
          <dynamics>
            <damping>0</damping>
            <friction>0</friction>
            <spring_reference>0</spring_reference>
            <spring_stiffness>0</spring_stiffness>
          </dynamics>
          <limit>
            <lower>-1.5708</lower>
            <upper>1.5708</upper>
            <effort>0</effort>
            <velocity>0</velocity>
          </limit>
          <xyz>0 1 0</xyz>
          <use_parent_model_frame>1</use_parent_model_frame>
        </axis>
      </joint>
      <joint name='r_foot_joint' type='revolute'>
        <parent>r_ankle</parent>
        <child>r_foot</child>
        <axis>
          <dynamics>
            <damping>0</damping>
            <friction>0</friction>
            <spring_reference>0</spring_reference>
            <spring_stiffness>0</spring_stiffness>
          </dynamics>
          <limit>
            <lower>-1.5708</lower>
            <upper>1.5708</upper>
            <effort>0</effort>
            <velocity>0</velocity>
          </limit>
          <xyz>1 0 0</xyz>
          <use_parent_model_frame>1</use_parent_model_frame>
        </axis>
      </joint>
      <joint name='torso_joint' type='revolute'>
        <parent>hip</parent>
        <child>torso</child>
        <axis>
          <dynamics>
            <damping>0</damping>
            <friction>0</friction>
            <spring_reference>0</spring_reference>
            <spring_stiffness>0</spring_stiffness>
          </dynamics>
          <limit>
            <lower>-1.5708</lower>
            <upper>1.5708</upper>
            <effort>0</effort>
            <velocity>0</velocity>
          </limit>
          <xyz>0 1 0</xyz>
          <use_parent_model_frame>1</use_parent_model_frame>
        </axis>
      </joint>
      <joint name='l_shoulder_joint' type='revolute'>
        <parent>torso</parent>
        <child>l_shoulder</child>
        <axis>
          <dynamics>
            <damping>0</damping>
            <friction>0</friction>
            <spring_reference>0</spring_reference>
            <spring_stiffness>0</spring_stiffness>
          </dynamics>
          <limit>
            <lower>-1.5708</lower>
            <upper>1.5708</upper>
            <effort>0</effort>
            <velocity>0</velocity>
          </limit>
          <xyz>1 0 0</xyz>
          <use_parent_model_frame>1</use_parent_model_frame>
        </axis>
      </joint>
      <joint name='l_upper_arm_joint' type='revolute'>
        <parent>l_shoulder</parent>
        <child>l_upper_arm</child>
        <axis>
          <dynamics>
            <damping>0</damping>
            <friction>0</friction>
            <spring_reference>0</spring_reference>
            <spring_stiffness>0</spring_stiffness>
          </dynamics>
          <limit>
            <lower>-1.5708</lower>
            <upper>1.5708</upper>
            <effort>0</effort>
            <velocity>0</velocity>
          </limit>
          <xyz>0 1 0</xyz>
          <use_parent_model_frame>1</use_parent_model_frame>
        </axis>
      </joint>
      <joint name='l_forearm_joint' type='revolute'>
        <parent>l_upper_arm</parent>
        <child>l_forearm</child>
        <axis>
          <dynamics>
            <damping>0</damping>
            <friction>0</friction>
            <spring_reference>0</spring_reference>
            <spring_stiffness>0</spring_stiffness>
          </dynamics>
          <limit>
            <lower>-1.5708</lower>
            <upper>1.5708</upper>
            <effort>0</effort>
            <velocity>0</velocity>
          </limit>
          <xyz>0 1 0</xyz>
          <use_parent_model_frame>1</use_parent_model_frame>
        </axis>
      </joint>
      <joint name='l_wrist_joint' type='revolute'>
        <parent>l_forearm</parent>
        <child>l_wrist</child>
        <axis>
          <dynamics>
            <damping>0</damping>
            <friction>0</friction>
            <spring_reference>0</spring_reference>
            <spring_stiffness>0</spring_stiffness>
          </dynamics>
          <limit>
            <lower>-1.5708</lower>
            <upper>1.5708</upper>
            <effort>0</effort>
            <velocity>0</velocity>
          </limit>
          <xyz>0 1 0</xyz>
          <use_parent_model_frame>1</use_parent_model_frame>
        </axis>
      </joint>
      <joint name='l_hand_joint' type='revolute'>
        <parent>l_wrist</parent>
        <child>l_hand</child>
        <axis>
          <dynamics>
            <damping>0</damping>
            <friction>0</friction>
            <spring_reference>0</spring_reference>
            <spring_stiffness>0</spring_stiffness>
          </dynamics>
          <limit>
            <lower>-1.5708</lower>
            <upper>1.5708</upper>
            <effort>0</effort>
            <velocity>0</velocity>
          </limit>
          <xyz>0 1 0</xyz>
          <use_parent_model_frame>1</use_parent_model_frame>
        </axis>
      </joint>
      <joint name='neck_joint' type='revolute'>
        <parent>torso</parent>
        <child>neck</child>
        <axis>
          <dynamics>
            <damping>0</damping>
            <friction>0</friction>
            <spring_reference>0</spring_reference>
            <spring_stiffness>0</spring_stiffness>
          </dynamics>
          <limit>
            <lower>-1.5708</lower>
            <upper>1.5708</upper>
            <effort>0</effort>
            <velocity>0</velocity>
          </limit>
          <xyz>0 0 1</xyz>
          <use_parent_model_frame>1</use_parent_model_frame>
        </axis>
      </joint>
      <joint name='head_joint' type='revolute'>
        <parent>neck</parent>
        <child>head</child>
        <axis>
          <dynamics>
            <damping>0</damping>
            <friction>0</friction>
            <spring_reference>0</spring_reference>
            <spring_stiffness>0</spring_stiffness>
          </dynamics>
          <limit>
            <lower>-1.5708</lower>
            <upper>1.5708</upper>
            <effort>0</effort>
            <velocity>0</velocity>
          </limit>
          <xyz>0 1 0</xyz>
          <use_parent_model_frame>1</use_parent_model_frame>
        </axis>
      </joint>
      <joint name='r_shoulder_joint' type='revolute'>
        <parent>torso</parent>
        <child>r_shoulder</child>
        <axis>
          <dynamics>
            <damping>0</damping>
            <friction>0</friction>
            <spring_reference>0</spring_reference>
            <spring_stiffness>0</spring_stiffness>
          </dynamics>
          <limit>
            <lower>-1.5708</lower>
            <upper>1.5708</upper>
            <effort>0</effort>
            <velocity>0</velocity>
          </limit>
          <xyz>1 0 0</xyz>
          <use_parent_model_frame>1</use_parent_model_frame>
        </axis>
      </joint>
      <joint name='r_upper_arm_joint' type='revolute'>
        <parent>r_shoulder</parent>
        <child>r_upper_arm</child>
        <axis>
          <dynamics>
            <damping>0</damping>
            <friction>0</friction>
            <spring_reference>0</spring_reference>
            <spring_stiffness>0</spring_stiffness>
          </dynamics>
          <limit>
            <lower>-1.5708</lower>
            <upper>1.5708</upper>
            <effort>0</effort>
            <velocity>0</velocity>
          </limit>
          <xyz>0 1 0</xyz>
          <use_parent_model_frame>1</use_parent_model_frame>
        </axis>
      </joint>
      <joint name='r_forearm_joint' type='revolute'>
        <parent>r_upper_arm</parent>
        <child>r_forearm</child>
        <axis>
          <dynamics>
            <damping>0</damping>
            <friction>0</friction>
            <spring_reference>0</spring_reference>
            <spring_stiffness>0</spring_stiffness>
          </dynamics>
          <limit>
            <lower>-1.5708</lower>
            <upper>1.5708</upper>
            <effort>0</effort>
            <velocity>0</velocity>
          </limit>
          <xyz>0 1 0</xyz>
          <use_parent_model_frame>1</use_parent_model_frame>
        </axis>
      </joint>
      <joint name='r_wrist_joint' type='revolute'>
        <parent>r_forearm</parent>
        <child>r_wrist</child>
        <axis>
          <dynamics>
            <damping>0</damping>
            <friction>0</friction>
            <spring_reference>0</spring_reference>
            <spring_stiffness>0</spring_stiffness>
          </dynamics>
          <limit>
            <lower>-1.5708</lower>
            <upper>1.5708</upper>
            <effort>0</effort>
            <velocity>0</velocity>
          </limit>
          <xyz>0 1 0</xyz>
          <use_parent_model_frame>1</use_parent_model_frame>
        </axis>
      </joint>
      <joint name='r_hand_joint' type='revolute'>
        <parent>r_wrist</parent>
        <child>r_hand</child>
        <axis>
          <dynamics>
            <damping>0</damping>
            <friction>0</friction>
            <spring_reference>0</spring_reference>
            <spring_stiffness>0</spring_stiffness>
          </dynamics>
          <limit>
            <lower>-1.5708</lower>
            <upper>1.5708</upper>
            <effort>0</effort>
            <velocity>0</velocity>
          </limit>
          <xyz>0 1 0</xyz>
          <use_parent_model_frame>1</use_parent_model_frame>
        </axis>
      </joint>
      <static>0</static>
    </model>
    <model name='person_walking'>
      <link name='link'>
        <inertial>
          <pose frame=''>0 0 0.95 0 -0 0</pose>
          <mass>80</mass>
          <inertia>
            <ixx>27.82</ixx>
            <ixy>0</ixy>
            <ixz>0</ixz>
            <iyy>24.88</iyy>
            <iyz>0</iyz>
            <izz>4.57</izz>
          </inertia>
        </inertial>
        <collision name='bottom'>
          <pose frame=''>0 0 0.01 0 -0 0</pose>
          <geometry>
            <box>
              <size>0.35 0.75 0.02</size>
            </box>
          </geometry>
          <max_contacts>10</max_contacts>
          <surface>
            <contact>
              <ode/>
            </contact>
            <bounce/>
            <friction>
              <torsional>
                <ode/>
              </torsional>
              <ode/>
            </friction>
          </surface>
        </collision>
        <collision name='person'>
          <pose frame=''>0 0 -0.02 0 -0 0</pose>
          <geometry>
            <mesh>
              <uri>model://person_walking/meshes/walking.dae</uri>
            </mesh>
          </geometry>
          <max_contacts>10</max_contacts>
          <surface>
            <contact>
              <ode/>
            </contact>
            <bounce/>
            <friction>
              <torsional>
                <ode/>
              </torsional>
              <ode/>
            </friction>
          </surface>
        </collision>
        <visual name='visual'>
          <pose frame=''>0 0 -0.02 0 -0 0</pose>
          <geometry>
            <mesh>
              <uri>model://person_walking/meshes/walking.dae</uri>
            </mesh>
          </geometry>
        </visual>
        <self_collide>0</self_collide>
        <enable_wind>0</enable_wind>
        <kinematic>0</kinematic>
      </link>
      <pose frame=''>7.77387 5.47767 0 0 -0 0</pose>
    </model>
    <state world_name='default'>
      <sim_time>231 890000000</sim_time>
      <real_time>233 350767906</real_time>
      <wall_time>1575231501 390913839</wall_time>
      <iterations>231890</iterations>
      <model name='ground_plane'>
        <pose frame=''>0 0 0 0 -0 0</pose>
        <scale>1 1 1</scale>
        <link name='link'>
          <pose frame=''>0 0 0 0 -0 0</pose>
          <velocity>0 0 0 0 -0 0</velocity>
          <acceleration>0 0 0 0 -0 0</acceleration>
          <wrench>0 0 0 0 -0 0</wrench>
        </link>
      </model>
      <model name='husarion-flat'>
        <pose frame=''>12.8358 -0.443938 0 0 -0 0</pose>
        <scale>1 1 1</scale>
        <link name='Wall_0'>
          <pose frame=''>14.4216 -7.02688 0 0 -0 0</pose>
          <velocity>0 0 0 0 -0 0</velocity>
          <acceleration>0 0 0 0 -0 0</acceleration>
          <wrench>0 0 0 0 -0 0</wrench>
        </link>
        <link name='Wall_1'>
          <pose frame=''>24.9716 -0.47688 0 0 -0 1.5708</pose>
          <velocity>0 0 0 0 -0 0</velocity>
          <acceleration>0 0 0 0 -0 0</acceleration>
          <wrench>0 0 0 0 -0 0</wrench>
        </link>
        <link name='Wall_11'>
          <pose frame=''>2.94067 -5.30328 0 0 0 -1.5708</pose>
          <velocity>0 0 0 0 -0 0</velocity>
          <acceleration>0 0 0 0 -0 0</acceleration>
          <wrench>0 0 0 0 -0 0</wrench>
        </link>
        <link name='Wall_13'>
          <pose frame=''>3.55185 -3.62828 0 0 -0 0</pose>
          <velocity>0 0 0 0 -0 0</velocity>
          <acceleration>0 0 0 0 -0 0</acceleration>
          <wrench>0 0 0 0 -0 0</wrench>
        </link>
        <link name='Wall_16'>
          <pose frame=''>8.65185 -3.62828 0 0 -0 0</pose>
          <velocity>0 0 0 0 -0 0</velocity>
          <acceleration>0 0 0 0 -0 0</acceleration>
          <wrench>0 0 0 0 -0 0</wrench>
        </link>
        <link name='Wall_18'>
          <pose frame=''>16.2101 -5.39564 0 0 -0 1.5708</pose>
          <velocity>0 0 0 0 -0 0</velocity>
          <acceleration>0 0 0 0 -0 0</acceleration>
          <wrench>0 0 0 0 -0 0</wrench>
        </link>
        <link name='Wall_19'>
          <pose frame=''>17.8851 -3.84564 0 0 -0 0</pose>
          <velocity>0 0 0 0 -0 0</velocity>
          <acceleration>0 0 0 0 -0 0</acceleration>
          <wrench>0 0 0 0 -0 0</wrench>
        </link>
        <link name='Wall_2'>
          <pose frame=''>14.5466 6.07312 0 0 -0 3.14159</pose>
          <velocity>0 0 0 0 -0 0</velocity>
          <acceleration>0 0 0 0 -0 0</acceleration>
          <wrench>0 0 0 0 -0 0</wrench>
        </link>
        <link name='Wall_21'>
          <pose frame=''>23.4794 -3.79011 0 0 -0 3.14159</pose>
          <velocity>0 0 0 0 -0 0</velocity>
          <acceleration>0 0 0 0 -0 0</acceleration>
          <wrench>0 0 0 0 -0 0</wrench>
        </link>
        <link name='Wall_23'>
          <pose frame=''>6.54661 -1.27688 0 0 -0 0</pose>
          <velocity>0 0 0 0 -0 0</velocity>
          <acceleration>0 0 0 0 -0 0</acceleration>
          <wrench>0 0 0 0 -0 0</wrench>
        </link>
        <link name='Wall_25'>
          <pose frame=''>15.6813 -1.28186 0 0 -0 0</pose>
          <velocity>0 0 0 0 -0 0</velocity>
          <acceleration>0 0 0 0 -0 0</acceleration>
          <wrench>0 0 0 0 -0 0</wrench>
        </link>
        <link name='Wall_27'>
          <pose frame=''>23.4644 -1.28186 0 0 -0 0</pose>
          <velocity>0 0 0 0 -0 0</velocity>
          <acceleration>0 0 0 0 -0 0</acceleration>
          <wrench>0 0 0 0 -0 0</wrench>
        </link>
        <link name='Wall_29'>
          <pose frame=''>15.7651 2.464 0 0 0 -1.5708</pose>
          <velocity>0 0 0 0 -0 0</velocity>
          <acceleration>0 0 0 0 -0 0</acceleration>
          <wrench>0 0 0 0 -0 0</wrench>
        </link>
        <link name='Wall_3'>
          <pose frame=''>4.12161 2.39812 0 0 0 -1.5708</pose>
          <velocity>0 0 0 0 -0 0</velocity>
          <acceleration>0 0 0 0 -0 0</acceleration>
          <wrench>0 0 0 0 -0 0</wrench>
        </link>
        <link name='Wall_31'>
          <pose frame=''>15.7526 -3.74636 0 0 -0 3.14159</pose>
          <velocity>0 0 0 0 -0 0</velocity>
          <acceleration>0 0 0 0 -0 0</acceleration>
          <wrench>0 0 0 0 -0 0</wrench>
        </link>
        <link name='Wall_4'>
          <pose frame=''>3.57161 -1.27688 0 0 -0 3.14159</pose>
          <velocity>0 0 0 0 -0 0</velocity>
          <acceleration>0 0 0 0 -0 0</acceleration>
          <wrench>0 0 0 0 -0 0</wrench>
        </link>
        <link name='Wall_5'>
          <pose frame=''>3.02161 0.27312 0 0 -0 1.5708</pose>
          <velocity>0 0 0 0 -0 0</velocity>
          <acceleration>0 0 0 0 -0 0</acceleration>
          <wrench>0 0 0 0 -0 0</wrench>
        </link>
        <link name='Wall_6'>
          <pose frame=''>0.721569 1.82312 0 0 -0 3.14159</pose>
          <velocity>0 0 0 0 -0 0</velocity>
          <acceleration>0 0 0 0 -0 0</acceleration>
          <wrench>0 0 0 0 -0 0</wrench>
        </link>
        <link name='Wall_7'>
          <pose frame=''>-1.57843 -2.60188 0 0 0 -1.5708</pose>
          <velocity>0 0 0 0 -0 0</velocity>
          <acceleration>0 0 0 0 -0 0</acceleration>
          <wrench>0 0 0 0 -0 0</wrench>
        </link>
        <link name='Wall_8'>
          <pose frame=''>1.14657 -7.02688 0 0 -0 0</pose>
          <velocity>0 0 0 0 -0 0</velocity>
          <acceleration>0 0 0 0 -0 0</acceleration>
          <wrench>0 0 0 0 -0 0</wrench>
        </link>
      </model>
      <model name='person_walking'>
        <pose frame=''>7.77387 5.47767 -1e-06 -2e-06 1e-06 0.000288</pose>
        <scale>1 1 1</scale>
        <link name='link'>
          <pose frame=''>7.77387 5.47767 -1e-06 -2e-06 1e-06 0.000288</pose>
          <velocity>0 0 0 0 -0 0</velocity>
          <acceleration>0.962298 2.02916 -2.69771 -2.11654 1.05464 0.105489</acceleration>
          <wrench>76.9839 162.333 -215.817 0 -0 0</wrench>
        </link>
      </model>
      <model name='ragdoll'>
        <pose frame=''>16.2688 2.73099 1.39998 1e-06 -0.000567 -0.026357</pose>
        <scale>1 1 1</scale>
        <link name='head'>
          <pose frame=''>16.2687 2.73099 2.62498 2e-06 -0 0</pose>
          <velocity>-0 -4e-06 2.1e-05 -4e-06 0 0</velocity>
          <acceleration>-2e-05 -0.000651 -0.003577 0.00487 -0 0</acceleration>
          <wrench>-0.000204 -0.006509 -0.035768 0 -0 0</wrench>
        </link>
        <link name='hip'>
          <pose frame=''>16.2688 2.73099 1.39998 1e-06 -0.000567 -0.026357</pose>
          <velocity>3e-06 -9e-06 2.1e-05 -3e-06 -1.5e-05 -0.000125</velocity>
          <acceleration>-7.1e-05 3.7e-05 -0.003346 -0.001428 0.000436 0.000134</acceleration>
          <wrench>-0.00071 0.000373 -0.033459 0 -0 0</wrench>
        </link>
        <link name='l_ankle'>
          <pose frame=''>16.2686 2.95089 0.075 -1.5e-05 4e-06 0.000348</pose>
          <velocity>-2e-06 -4.2e-05 1.7e-05 -1.7e-05 -8e-06 1.1e-05</velocity>
          <acceleration>-2.3e-05 -0.083277 -0.000893 -0.053956 -0.002856 0.014506</acceleration>
          <wrench>-2.3e-05 -0.083277 -0.000893 0 -0 0</wrench>
        </link>
        <link name='l_calf'>
          <pose frame=''>16.2692 2.9509 0.699999 -1.5e-05 0.000933 0.000348</pose>
          <velocity>-4e-06 -2.9e-05 1.9e-05 -1.9e-05 -3e-06 7e-06</velocity>
          <acceleration>0.000437 -0.046479 -0.001109 -0.057021 0.000741 0.006497</acceleration>
          <wrench>0.000874 -0.092957 -0.002219 0 -0 0</wrench>
        </link>
        <link name='l_foot'>
          <pose frame=''>16.2686 2.95089 0.05 1e-06 6e-06 0.000348</pose>
          <velocity>-2e-06 -3.9e-05 1.3e-05 0.000773 -3.6e-05 -0</velocity>
          <acceleration>4.9e-05 -0.078408 -0.000499 1.56815 0.000985 -9e-06</acceleration>
          <wrench>4.9e-05 -0.078408 -0.000499 0 -0 0</wrench>
        </link>
        <link name='l_forearm'>
          <pose frame=''>16.2691 3.05851 1.72253 -0.000139 0.000912 -0.026357</pose>
          <velocity>3e-06 -2e-06 2.1e-05 4e-06 6e-06 -0.000125</velocity>
          <acceleration>-0.000128 2.6e-05 -0.003456 -8.7e-05 -0.000262 0.000369</acceleration>
          <wrench>-0.000128 2.6e-05 -0.003456 0 -0 0</wrench>
        </link>
        <link name='l_hand'>
          <pose frame=''>16.2687 3.05845 1.24253 -0.000139 -1e-06 -0.026357</pose>
          <velocity>0 0 2.1e-05 4e-06 0 -0.000125</velocity>
          <acceleration>-6e-06 -5e-06 -0.003448 -7.8e-05 2e-06 0.000363</acceleration>
          <wrench>-6e-06 -5e-06 -0.003448 0 -0 0</wrench>
        </link>
        <link name='l_shoulder'>
          <pose frame=''>16.2773 3.05837 2.32248 -0.000139 5.5e-05 -0.026357</pose>
          <velocity>4.1e-05 -6e-06 2e-05 4e-06 1e-06 -0.000125</velocity>
          <acceleration>-0.000102 4.9e-05 -0.00344 -5.5e-05 -5.9e-05 0.000358</acceleration>
          <wrench>-0.000102 4.9e-05 -0.00344 0 -0 0</wrench>
        </link>
        <link name='l_thigh_lift'>
          <pose frame=''>16.2746 2.95091 1.39998 -1.5e-05 0.007737 0.000348</pose>
          <velocity>3e-05 -1e-05 1.9e-05 -2.6e-05 4.9e-05 5e-06</velocity>
          <acceleration>-0.000129 -0.001165 -0.001218 -0.065858 -0.000776 0.002161</acceleration>
          <wrench>-0.000646 -0.005825 -0.006089 0 -0 0</wrench>
        </link>
        <link name='l_thigh_pan'>
          <pose frame=''>16.2746 2.95091 1.39998 -1.5e-05 -0.000567 0.000348</pose>
          <velocity>3e-05 -1e-05 1.9e-05 -2.9e-05 -1.5e-05 4e-06</velocity>
          <acceleration>-0.000134 -0.00135 -0.001158 -0.074648 0.000409 0.000627</acceleration>
          <wrench>-0.000134 -0.00135 -0.001158 0 -0 0</wrench>
        </link>
        <link name='l_upper_arm'>
          <pose frame=''>16.2773 3.05837 2.32248 -0.000139 0.013638 -0.026359</pose>
          <velocity>4.1e-05 -6e-06 2e-05 6e-06 6.3e-05 -0.000125</velocity>
          <acceleration>-9.9e-05 4.7e-05 -0.003435 -4.9e-05 3e-05 0.000354</acceleration>
          <wrench>-0.000198 9.5e-05 -0.006871 0 -0 0</wrench>
        </link>
        <link name='l_wrist'>
          <pose frame=''>16.2687 3.05845 1.25753 -0.000139 1.3e-05 -0.026357</pose>
          <velocity>0 0 2.1e-05 4e-06 0 -0.000125</velocity>
          <acceleration>-6e-06 -5e-06 -0.003457 -8.1e-05 -7e-06 0.00037</acceleration>
          <wrench>-6e-06 -5e-06 -0.003457 0 -0 0</wrench>
        </link>
        <link name='neck'>
          <pose frame=''>16.2687 2.73099 2.34998 2e-06 5.5e-05 0</pose>
          <velocity>-0 -5e-06 2.2e-05 -4e-06 1e-06 0</velocity>
          <acceleration>1.9e-05 9.2e-05 -0.003634 0.005148 -0.000197 0</acceleration>
          <wrench>1.9e-05 9.2e-05 -0.003634 0 -0 0</wrench>
        </link>
        <link name='r_ankle'>
          <pose frame=''>16.2686 2.51104 0.075 -1.4e-05 8e-06 -0.000398</pose>
          <velocity>-2e-06 3.8e-05 1.6e-05 2.8e-05 -3e-06 -7e-06</velocity>
          <acceleration>-0.000162 0.079632 -0.002017 0.043779 -0.006724 -0.022036</acceleration>
          <wrench>-0.000162 0.079632 -0.002017 0 -0 0</wrench>
        </link>
        <link name='r_calf'>
          <pose frame=''>16.2685 2.51105 0.7 -1.4e-05 -0.000173 -0.000398</pose>
          <velocity>-6e-06 1.8e-05 1.8e-05 3e-05 -7e-06 -2e-06</velocity>
          <acceleration>-0.000362 0.047347 -0.00247 0.04753 -0.000307 -0.01351</acceleration>
          <wrench>-0.000723 0.094694 -0.00494 0 -0 0</wrench>
        </link>
        <link name='r_foot'>
          <pose frame=''>16.2686 2.51104 0.05 -1e-06 1e-05 -0.000398</pose>
          <velocity>-2e-06 3.5e-05 1.2e-05 -0.000703 -3.2e-05 0</velocity>
          <acceleration>4.7e-05 0.073067 -0.001182 -1.46132 0.000944 1.3e-05</acceleration>
          <wrench>4.7e-05 0.073067 -0.001182 0 -0 0</wrench>
        </link>
        <link name='r_forearm'>
          <pose frame=''>16.2683 2.40343 1.72253 8.1e-05 -0.000918 -0.026357</pose>
          <velocity>-3e-06 -3e-06 2.3e-05 7e-06 -6e-06 -0.000125</velocity>
          <acceleration>0.000138 0.00025 -0.003465 -0.000518 0.000286 0.000353</acceleration>
          <wrench>0.000138 0.00025 -0.003465 0 -0 0</wrench>
        </link>
        <link name='r_hand'>
          <pose frame=''>16.2687 2.40346 1.24253 8.1e-05 1e-06 -0.026357</pose>
          <velocity>-0 1e-06 2.3e-05 7e-06 -0 -0.000125</velocity>
          <acceleration>5e-06 -6e-05 -0.003533 -0.000761 2e-05 0.00041</acceleration>
          <wrench>5e-06 -6e-05 -0.003533 0 -0 0</wrench>
        </link>
        <link name='r_shoulder'>
          <pose frame=''>16.2601 2.4036 2.32248 8.1e-05 5.5e-05 -0.026357</pose>
          <velocity>-4.1e-05 -5e-06 2.2e-05 7e-06 1e-06 -0.000125</velocity>
          <acceleration>0.000117 0.000516 -0.003367 -0.000604 -7e-06 0.000264</acceleration>
          <wrench>0.000117 0.000516 -0.003367 0 -0 0</wrench>
        </link>
        <link name='r_thigh_lift'>
          <pose frame=''>16.263 2.51106 1.39998 -1.4e-05 -0.00783 -0.000398</pose>
          <velocity>-2.5e-05 -7e-06 1.9e-05 3.6e-05 -2.7e-05 0</velocity>
          <acceleration>4e-06 0.001508 -0.002706 0.063137 0.000462 -0.008802</acceleration>
          <wrench>1.9e-05 0.007541 -0.013531 0 -0 0</wrench>
        </link>
        <link name='r_thigh_pan'>
          <pose frame=''>16.263 2.51106 1.39998 -1.4e-05 -0.000567 -0.000398</pose>
          <velocity>-2.5e-05 -7e-06 1.9e-05 4e-05 -1.5e-05 1e-06</velocity>
          <acceleration>7e-06 0.001707 -0.002652 0.071081 0.000442 -0.00733</acceleration>
          <wrench>7e-06 0.001707 -0.002652 0 -0 0</wrench>
        </link>
        <link name='r_upper_arm'>
          <pose frame=''>16.2601 2.4036 2.32248 8.1e-05 -0.013681 -0.026358</pose>
          <velocity>-4.1e-05 -5e-06 2.3e-05 5e-06 -6.4e-05 -0.000125</velocity>
          <acceleration>0.000131 0.000547 -0.00344 -0.000609 1.6e-05 0.000329</acceleration>
          <wrench>0.000261 0.001093 -0.00688 0 -0 0</wrench>
        </link>
        <link name='r_wrist'>
          <pose frame=''>16.2687 2.40346 1.25753 8.1e-05 -1.4e-05 -0.026357</pose>
          <velocity>-0 0 2.3e-05 7e-06 -0 -0.000125</velocity>
          <acceleration>5e-06 -4.6e-05 -0.003504 -0.00072 2.8e-05 0.000385</acceleration>
          <wrench>5e-06 -4.6e-05 -0.003504 0 -0 0</wrench>
        </link>
        <link name='torso'>
          <pose frame=''>16.2687 2.73099 1.64998 1e-06 5.5e-05 -0.026357</pose>
          <velocity>-1e-06 -8e-06 2.1e-05 -3e-06 1e-06 -0.000125</velocity>
          <acceleration>4.5e-05 0.000341 -0.003437 -0.000194 -5.6e-05 0.000252</acceleration>
          <wrench>0.001352 0.010243 -0.103112 0 -0 0</wrench>
        </link>
      </model>



      <light name='sun'>
        <pose frame=''>0 0 10 0 -0 0</pose>
      </light>
    </state>
    <gui fullscreen='0'>
      <camera name='user_camera'>
        <pose frame=''>16.0824 -12.8431 22.1871 0 1.0258 1.88901</pose>
        <view_controller>orbit</view_controller>
        <projection_type>perspective</projection_type>
      </camera>
    </gui>


<model name='model1'>
      <pose frame=''>0 0 0 0 -0 0</pose>
      <link name='link1'>
        <pose frame=''>0 0 0 0 -0 0</pose>
        <visual name='visual_box1'>
          <pose frame=''>0 0 0 0 -0 0</pose>
          <geometry>
            <box>
              <size>0.05 0.05 0.05</size>
            </box>
          </geometry>
          <cast_shadows>1</cast_shadows>
          <laser_retro>100</laser_retro>
        </visual>
        <collision name='collision_box6'>
          <pose frame=''>0 0 -0.5 0 -0 0</pose>
          <max_contacts>250</max_contacts>
          <geometry>
            <box>
              <size>0.05 0.05 0.05</size>
            </box>
          </geometry>
          <surface>
            <friction>
              <ode>
                <mu>0.5</mu>
                <mu2>0.2</mu2>
                <fdir1>1 0 0</fdir1>
                <slip1>0</slip1>
                <slip2>0</slip2>
              </ode>
              <torsional>
                <ode/>
              </torsional>
            </friction>
            <bounce>
              <restitution_coefficient>0</restitution_coefficient>
              <threshold>1e+06</threshold>
            </bounce>
            <contact>
              <ode>
                <soft_cfm>0</soft_cfm>
                <soft_erp>0.2</soft_erp>
                <kp>1e+15</kp>
                <kd>1e+13</kd>
                <max_vel>100</max_vel>
                <min_depth>0.0001</min_depth>
              </ode>
            </contact>
          </surface>
          <laser_retro>100</laser_retro>
        </collision>
        <sensor name='sonar1' type='ray'>
          <pose frame=''>0.25 0 0 0 -0 0</pose>
          <update_rate>5</update_rate>
          <ray>
            <scan>
              <horizontal>
                <samples>5</samples>
                <resolution>1</resolution>
                <min_angle>-0.25</min_angle>
                <max_angle>0.25</max_angle>
              </horizontal>
              <vertical>
                <samples>5</samples>
                <resolution>1</resolution>
                <min_angle>-0.25</min_angle>
                <max_angle>0.25</max_angle>
              </vertical>
            </scan>
            <range>
              <min>0.01</min>
              <max>5.5</max>
              <resolution>0.01</resolution>
            </range>
          </ray>
          <plugin name='gazebo_ros_range' filename='libgazebo_ros_range.so'>
            <gaussianNoise>0.005</gaussianNoise>
            <alwaysOn>true</alwaysOn>
            <updateRate>5</updateRate>
            <topicName>sonar1</topicName>
            <frameName>sonar1_link</frameName>
            <fov>0.5</fov>
            <radiation>ultrasound</radiation>
          </plugin>
        </sensor>
        <gravity>0</gravity>
        <self_collide>1</self_collide>
        <kinematic>0</kinematic>
      </link>
      <static>1</static>
    </model>

<model name='model2'>
      <pose frame=''>0 0 0 0 -0 0</pose>
      <link name='link2'>
        <pose frame=''>0 0 0 0 -0 0</pose>
        <visual name='visual_box2'>
          <pose frame=''>0 0 0 0 -0 0</pose>
          <geometry>
            <box>
              <size>0.05 0.05 0.05</size>
            </box>
          </geometry>
          <cast_shadows>1</cast_shadows>
          <laser_retro>100</laser_retro>
        </visual>
        <collision name='collision_box6'>
          <pose frame=''>0 0 -0.5 0 -0 0</pose>
          <max_contacts>250</max_contacts>
          <geometry>
            <box>
              <size>0.05 0.05 0.05</size>
            </box>
          </geometry>
          <surface>
            <friction>
              <ode>
                <mu>0.5</mu>
                <mu2>0.2</mu2>
                <fdir1>1 0 0</fdir1>
                <slip1>0</slip1>
                <slip2>0</slip2>
              </ode>
              <torsional>
                <ode/>
              </torsional>
            </friction>
            <bounce>
              <restitution_coefficient>0</restitution_coefficient>
              <threshold>1e+06</threshold>
            </bounce>
            <contact>
              <ode>
                <soft_cfm>0</soft_cfm>
                <soft_erp>0.2</soft_erp>
                <kp>1e+15</kp>
                <kd>1e+13</kd>
                <max_vel>100</max_vel>
                <min_depth>0.0001</min_depth>
              </ode>
            </contact>
          </surface>
          <laser_retro>100</laser_retro>
        </collision>
        <sensor name='sonar2' type='ray'>
          <pose frame=''>0.25 0 0 0 -0 0</pose>
          <update_rate>5</update_rate>
          <ray>
            <scan>
              <horizontal>
                <samples>5</samples>
                <resolution>1</resolution>
                <min_angle>-0.25</min_angle>
                <max_angle>0.25</max_angle>
              </horizontal>
              <vertical>
                <samples>5</samples>
                <resolution>1</resolution>
                <min_angle>-0.25</min_angle>
                <max_angle>0.25</max_angle>
              </vertical>
            </scan>
            <range>
              <min>0.01</min>
              <max>5.5</max>
              <resolution>0.01</resolution>
            </range>
          </ray>
          <plugin name='gazebo_ros_range' filename='libgazebo_ros_range.so'>
            <gaussianNoise>0.005</gaussianNoise>
            <alwaysOn>true</alwaysOn>
            <updateRate>5</updateRate>
            <topicName>sonar2</topicName>
            <frameName>sonar2_link</frameName>
            <fov>0.5</fov>
            <radiation>ultrasound</radiation>
          </plugin>
        </sensor>
        <gravity>0</gravity>
        <self_collide>1</self_collide>
        <kinematic>0</kinematic>
      </link>
      <static>1</static>
    </model>

    <model name='model3'>
      <pose frame=''>0 0 0 0 -0 0</pose>
      <link name='link3'>
        <pose frame=''>0 0 0 0 -0 0</pose>
        <visual name='visual_box3'>
          <pose frame=''>0 0 0 0 -0 0</pose>
          <geometry>
            <box>
              <size>0.05 0.05 0.05</size>
            </box>
          </geometry>
          <cast_shadows>1</cast_shadows>
          <laser_retro>100</laser_retro>
        </visual>
        <collision name='collision_box6'>
          <pose frame=''>0 0 -0.5 0 -0 0</pose>
          <max_contacts>250</max_contacts>
          <geometry>
            <box>
              <size>0.05 0.05 0.05</size>
            </box>
          </geometry>
          <surface>
            <friction>
              <ode>
                <mu>0.5</mu>
                <mu2>0.2</mu2>
                <fdir1>1 0 0</fdir1>
                <slip1>0</slip1>
                <slip2>0</slip2>
              </ode>
              <torsional>
                <ode/>
              </torsional>
            </friction>
            <bounce>
              <restitution_coefficient>0</restitution_coefficient>
              <threshold>1e+06</threshold>
            </bounce>
            <contact>
              <ode>
                <soft_cfm>0</soft_cfm>
                <soft_erp>0.2</soft_erp>
                <kp>1e+15</kp>
                <kd>1e+13</kd>
                <max_vel>100</max_vel>
                <min_depth>0.0001</min_depth>
              </ode>
            </contact>
          </surface>
          <laser_retro>100</laser_retro>
        </collision>
        <sensor name='sonar3' type='ray'>
          <pose frame=''>0.25 0 0 0 -0 0</pose>
          <update_rate>5</update_rate>
          <ray>
            <scan>
              <horizontal>
                <samples>5</samples>
                <resolution>1</resolution>
                <min_angle>-0.25</min_angle>
                <max_angle>0.25</max_angle>
              </horizontal>
              <vertical>
                <samples>5</samples>
                <resolution>1</resolution>
                <min_angle>-0.25</min_angle>
                <max_angle>0.25</max_angle>
              </vertical>
            </scan>
            <range>
              <min>0.01</min>
              <max>5.5</max>
              <resolution>0.01</resolution>
            </range>
          </ray>
          <plugin name='gazebo_ros_range' filename='libgazebo_ros_range.so'>
            <gaussianNoise>0.005</gaussianNoise>
            <alwaysOn>true</alwaysOn>
            <updateRate>5</updateRate>
            <topicName>sonar3</topicName>
            <frameName>sonar3_link</frameName>
            <fov>0.5</fov>
            <radiation>ultrasound</radiation>
          </plugin>
        </sensor>
        <gravity>0</gravity>
        <self_collide>1</self_collide>
        <kinematic>0</kinematic>
      </link>
      <static>1</static>
    </model>

<model name='model4'>
      <pose frame=''>0 0 0 0 -0 0</pose>
      <link name='link4'>
        <pose frame=''>0 0 0 0 -0 0</pose>
        <visual name='visual_box4'>
          <pose frame=''>0 0 0 0 -0 0</pose>
          <geometry>
            <box>
              <size>0.05 0.05 0.05</size>
            </box>
          </geometry>
          <cast_shadows>1</cast_shadows>
          <laser_retro>100</laser_retro>
        </visual>
        <collision name='collision_box6'>
          <pose frame=''>0 0 -0.5 0 -0 0</pose>
          <max_contacts>250</max_contacts>
          <geometry>
            <box>
              <size>0.05 0.05 0.05</size>
            </box>
          </geometry>
          <surface>
            <friction>
              <ode>
                <mu>0.5</mu>
                <mu2>0.2</mu2>
                <fdir1>1 0 0</fdir1>
                <slip1>0</slip1>
                <slip2>0</slip2>
              </ode>
              <torsional>
                <ode/>
              </torsional>
            </friction>
            <bounce>
              <restitution_coefficient>0</restitution_coefficient>
              <threshold>1e+06</threshold>
            </bounce>
            <contact>
              <ode>
                <soft_cfm>0</soft_cfm>
                <soft_erp>0.2</soft_erp>
                <kp>1e+15</kp>
                <kd>1e+13</kd>
                <max_vel>100</max_vel>
                <min_depth>0.0001</min_depth>
              </ode>
            </contact>
          </surface>
          <laser_retro>100</laser_retro>
        </collision>
        <sensor name='sonar4' type='ray'>
          <pose frame=''>0.25 0 0 0 -0 0</pose>
          <update_rate>5</update_rate>
          <ray>
            <scan>
              <horizontal>
                <samples>5</samples>
                <resolution>1</resolution>
                <min_angle>-0.25</min_angle>
                <max_angle>0.25</max_angle>
              </horizontal>
              <vertical>
                <samples>5</samples>
                <resolution>1</resolution>
                <min_angle>-0.25</min_angle>
                <max_angle>0.25</max_angle>
              </vertical>
            </scan>
            <range>
              <min>0.01</min>
              <max>5.5</max>
              <resolution>0.01</resolution>
            </range>
          </ray>
          <plugin name='gazebo_ros_range' filename='libgazebo_ros_range.so'>
            <gaussianNoise>0.005</gaussianNoise>
            <alwaysOn>true</alwaysOn>
            <updateRate>5</updateRate>
            <topicName>sonar4</topicName>
            <frameName>sonar4_link</frameName>
            <fov>0.5</fov>
            <radiation>ultrasound</radiation>
          </plugin>
        </sensor>
        <gravity>0</gravity>
        <self_collide>1</self_collide>
        <kinematic>0</kinematic>
      </link>
      <static>1</static>
    </model>

  </world>
</sdf>
